Workbook

Sheet 📋 Data Pasien
A1: 🏥 PEMBUKUAN KLINIK
A2: Pencatatan mulai Rabu, 01 April 2026 — Subtotal muncul otomatis setiap akhir tanggal
A3: 💡 CARA INPUT: Tanggal sudah terisi otomatis per blok hari. ① Nama Pasien ② Biaya Dokter ③ Jenis Bayar Dokter ▼ ④ Status Obat ▼ ⑤ Biaya Obat ⑥ Jenis Bayar Obat ▼ ⑦ Keterangan ▼
A4: 🟡 Cash = kuning 🔵 Transfer = biru 🔴 Tidak Ambil Obat = merah 🟢 Blok hijau = header hari 🔵 Subtotal biru = otomatis | F4: 📅 Mulai: 01 April 2026 | 15 slot pasien/hari | Format Accounting (Rp)
A5: No. | B5: Tanggal | C5: Nama Pasien | D5: Biaya Dokter (Rp) | E5: Jenis Bayar Dokter ▼ | F5: Status Obat ▼ | G5: Biaya Obat (Rp) | H5: Jenis Bayar Obat ▼ | I5: Total Biaya (Rp) | J5: Dokter Per Hari ▼ | K5: Keterangan ▼
A6: 📅 Rabu, 01 April 2026
A7: 1 | B7: 46113 | E7: ▼ | F7: ▼ | H7: ▼ | I7: =IF(C7="","",D7+IF(F7="Ambil Obat",IF(G7="",0,G7),0)) | K7: ▼
A8: 2 | B8: 46113 | E8: ▼ | F8: ▼ | H8: ▼ | I8: =IF(C8="","",D8+IF(F8="Ambil Obat",IF(G8="",0,G8),0)) | K8: ▼
A9: 3 | B9: 46113 | E9: ▼ | F9: ▼ | H9: ▼ | I9: =IF(C9="","",D9+IF(F9="Ambil Obat",IF(G9="",0,G9),0)) | K9: ▼
A10: 4 | B10: 46113 | E10: ▼ | F10: ▼ | H10: ▼ | I10: =IF(C10="","",D10+IF(F10="Ambil Obat",IF(G10="",0,G10),0)) | K10: ▼
A11: 5 | B11: 46113 | E11: ▼ | F11: ▼ | H11: ▼ | I11: =IF(C11="","",D11+IF(F11="Ambil Obat",IF(G11="",0,G11),0)) | K11: ▼
A12: 6 | B12: 46113 | E12: ▼ | F12: ▼ | H12: ▼ | I12: =IF(C12="","",D12+IF(F12="Ambil Obat",IF(G12="",0,G12),0)) | K12: ▼
A13: 7 | B13: 46113 | E13: ▼ | F13: ▼ | H13: ▼ | I13: =IF(C13="","",D13+IF(F13="Ambil Obat",IF(G13="",0,G13),0)) | K13: ▼
A14: 8 | B14: 46113 | E14: ▼ | F14: ▼ | H14: ▼ | I14: =IF(C14="","",D14+IF(F14="Ambil Obat",IF(G14="",0,G14),0)) | K14: ▼
A15: 9 | B15: 46113 | E15: ▼ | F15: ▼ | H15: ▼ | I15: =IF(C15="","",D15+IF(F15="Ambil Obat",IF(G15="",0,G15),0)) | K15: ▼
A16: 10 | B16: 46113 | E16: ▼ | F16: ▼ | H16: ▼ | I16: =IF(C16="","",D16+IF(F16="Ambil Obat",IF(G16="",0,G16),0)) | K16: ▼
A17: 11 | B17: 46113 | E17: ▼ | F17: ▼ | H17: ▼ | I17: =IF(C17="","",D17+IF(F17="Ambil Obat",IF(G17="",0,G17),0)) | K17: ▼
A18: =IF(COUNTA(C7:C17)=0,"— belum ada data —","📊 Sub-total "& TEXT(B7,"DD MMM YYYY") &" ("&COUNTA(C7:C17)&" pasien)") | D18: =IF(COUNTA(C7:C17)=0,"",SUM(D7:D17)) | E18: =IF(COUNTA(C7:C17)=0,"",SUMIF(E7:E17,"Cash",D7:D17)) | F18: =IF(COUNTA(C7:C17)=0,"",SUMIF(E7:E17,"Transfer Bank",D7:D17)) | G18: =IF(COUNTA(C7:C17)=0,"",SUMIF(F7:F17,"Ambil Obat",G7:G17)) | H18: =IF(COUNTA(C7:C17)=0,"",SUMIFS(G7:G17,H7:H17,"Cash",F7:F17,"Ambil Obat")) | I18: =IF(COUNTA(C7:C17)=0,"",SUMIFS(G7:G17,H7:H17,"Transfer Bank",F7:F17,"Ambil Obat")) | K18: =IF(COUNTA(C7:C17)=0,"",D18+G18)
A19: 📅 Kamis, 02 April 2026
A20: 1 | B20: 46114 | E20: ▼ | F20: ▼ | H20: ▼ | I20: =IF(C20="","",D20+IF(F20="Ambil Obat",IF(G20="",0,G20),0)) | K20: ▼
A21: 2 | B21: 46114 | E21: ▼ | F21: ▼ | H21: ▼ | I21: =IF(C21="","",D21+IF(F21="Ambil Obat",IF(G21="",0,G21),0)) | K21: ▼
A22: 3 | B22: 46114 | E22: ▼ | F22: ▼ | H22: ▼ | I22: =IF(C22="","",D22+IF(F22="Ambil Obat",IF(G22="",0,G22),0)) | K22: ▼
A23: 4 | B23: 46114 | E23: ▼ | F23: ▼ | H23: ▼ | I23: =IF(C23="","",D23+IF(F23="Ambil Obat",IF(G23="",0,G23),0)) | K23: ▼
A24: 5 | B24: 46114 | E24: ▼ | F24: ▼ | H24: ▼ | I24: =IF(C24="","",D24+IF(F24="Ambil Obat",IF(G24="",0,G24),0)) | K24: ▼
A25: 6 | B25: 46114 | E25: ▼ | F25: ▼ | H25: ▼ | I25: =IF(C25="","",D25+IF(F25="Ambil Obat",IF(G25="",0,G25),0)) | K25: ▼
A26: 7 | B26: 46114 | E26: ▼ | F26: ▼ | H26: ▼ | I26: =IF(C26="","",D26+IF(F26="Ambil Obat",IF(G26="",0,G26),0)) | K26: ▼
A27: =IF(COUNTA(C20:C26)=0,"— belum ada data —","📊 Sub-total "& TEXT(B20,"DD MMM YYYY") &" ("&COUNTA(C20:C26)&" pasien)") | D27: =IF(COUNTA(C20:C26)=0,"",SUM(D20:D26)) | E27: =IF(COUNTA(C20:C26)=0,"",SUMIF(E20:E26,"Cash",D20:D26)) | F27: =IF(COUNTA(C20:C26)=0,"",SUMIF(E20:E26,"Transfer Bank",D20:D26)) | G27: =IF(COUNTA(C20:C26)=0,"",SUMIF(F20:F26,"Ambil Obat",G20:G26)) | H27: =IF(COUNTA(C20:C26)=0,"",SUMIFS(G20:G26,H20:H26,"Cash",F20:F26,"Ambil Obat")) | I27: =IF(COUNTA(C20:C26)=0,"",SUMIFS(G20:G26,H20:H26,"Transfer Bank",F20:F26,"Ambil Obat")) | K27: =IF(COUNTA(C20:C26)=0,"",D27+G27)
A28: 📅 Jumat, 03 April 2026
A29: 1 | B29: 46115 | E29: ▼ | F29: ▼ | H29: ▼ | I29: =IF(C29="","",D29+IF(F29="Ambil Obat",IF(G29="",0,G29),0)) | K29: ▼
A30: 2 | B30: 46115 | E30: ▼ | F30: ▼ | H30: ▼ | I30: =IF(C30="","",D30+IF(F30="Ambil Obat",IF(G30="",0,G30),0)) | K30: ▼
A31: 3 | B31: 46115 | E31: ▼ | F31: ▼ | H31: ▼ | I31: =IF(C31="","",D31+IF(F31="Ambil Obat",IF(G31="",0,G31),0)) | K31: ▼
A32: 4 | B32: 46115 | E32: ▼ | F32: ▼ | H32: ▼ | I32: =IF(C32="","",D32+IF(F32="Ambil Obat",IF(G32="",0,G32),0)) | K32: ▼
A33: 5 | B33: 46115 | E33: ▼ | F33: ▼ | H33: ▼ | I33: =IF(C33="","",D33+IF(F33="Ambil Obat",IF(G33="",0,G33),0)) | K33: ▼
A34: 6 | B34: 46115 | E34: ▼ | F34: ▼ | H34: ▼ | I34: =IF(C34="","",D34+IF(F34="Ambil Obat",IF(G34="",0,G34),0)) | K34: ▼
A35: 7 | B35: 46115 | E35: ▼ | F35: ▼ | H35: ▼ | I35: =IF(C35="","",D35+IF(F35="Ambil Obat",IF(G35="",0,G35),0)) | K35: ▼
A36: =IF(C36="","",38) | B36: 46115 | C36: SITI H | D36: 300000 | E36: Transfer Bank | F36: Ambil Obat | G36: 20000 | H36: Transfer Bank | I36: =IF(C36="","",D36+IF(F36="Ambil Obat",IF(G36="",0,G36),0)) | K36: ▼
A37: =IF(C37="","",39) | B37: 46115 | C37: ZHAFIRA | D37: 250000 | E37: Cash | F37: Ambil Obat | G37: 140000 | H37: Cash | I37: =IF(C37="","",D37+IF(F37="Ambil Obat",IF(G37="",0,G37),0)) | K37: ▼
A38: =IF(C38="","",40) | B38: 46115 | C38: FAIZ A | D38: 300000 | E38: Cash | F38: ▼ | H38: ▼ | I38: =IF(C38="","",D38+IF(F38="Ambil Obat",IF(G38="",0,G38),0)) | K38: ▼
A39: =IF(C39="","",41) | B39: 46115 | C39: PUTRA A | D39: 300000 | E39: Cash | F39: ▼ | H39: ▼ | I39: =IF(C39="","",D39+IF(F39="Ambil Obat",IF(G39="",0,G39),0)) | K39: ▼
A40: =IF(COUNTA(C29:C39)=0,"— belum ada data —","📊 Sub-total "& TEXT(B29,"DD MMM YYYY") &" ("&COUNTA(C29:C39)&" pasien)") | D40: =IF(COUNTA(C29:C39)=0,"",SUM(D29:D39)) | E40: =IF(COUNTA(C29:C39)=0,"",SUMIF(E29:E39,"Cash",D29:D39)) | F40: =IF(COUNTA(C29:C39)=0,"",SUMIF(E29:E39,"Transfer Bank",D29:D39)) | G40: =IF(COUNTA(C29:C39)=0,"",SUMIF(F29:F39,"Ambil Obat",G29:G39)) | H40: =IF(COUNTA(C29:C39)=0,"",SUMIFS(G29:G39,H29:H39,"Cash",F29:F39,"Ambil Obat")) | I40: =IF(COUNTA(C29:C39)=0,"",SUMIFS(G29:G39,H29:H39,"Transfer Bank",F29:F39,"Ambil Obat")) | K40: =IF(COUNTA(C29:C39)=0,"",D40+G40)
...

Sheet Input Harian
A1: INPUT HARIAN – FEE DOKTER (OTOMATIS dari Data Pasien)
A2: ⚡ Isi kolom 🟡 KUNING saja: Tanggal (B) & Nama Dokter (C) → kolom lain otomatis terhitung dari Data Pasien
A3: No. | B3: Tanggal | C3: Nama Dokter ▼ | D3: Ps. 100rb | E3: Ps. 150rb | F3: Ps. 200rb | G3: Ps. 250rb | H3: Ps. 300rb | I3: Total Pasien | J3: Total 100rb | K3: Total 150rb | L3: Total 200rb | M3: Total 250rb | N3: Total 300rb | O3: Total Penarikan | P3: Fee Dokter | Q3: Keterangan | R3: Fee Klinik
A4: =IF(C4<>"",1,"") | D4: =IF(OR(B4="",C4=""),"",COUNTIFS('📋 Data Pasien'!$B:$B,B4,'📋 Data Pasien'!$J:$J,C4,'📋 Data Pasien'!$D:$D,100000)) | E4: =IF(OR(B4="",C4=""),"",COUNTIFS('📋 Data Pasien'!$B:$B,B4,'📋 Data Pasien'!$J:$J,C4,'📋 Data Pasien'!$D:$D,150000)) | F4: =IF(OR(B4="",C4=""),"",COUNTIFS('📋 Data Pasien'!$B:$B,B4,'📋 Data Pasien'!$J:$J,C4,'📋 Data Pasien'!$D:$D,200000)) | G4: =IF(OR(B4="",C4=""),"",COUNTIFS('📋 Data Pasien'!$B:$B,B4,'📋 Data Pasien'!$J:$J,C4,'📋 Data Pasien'!$D:$D,250000)) | H4: =IF(OR(B4="",C4=""),"",COUNTIFS('📋 Data Pasien'!$B:$B,B4,'📋 Data Pasien'!$J:$J,C4,'📋 Data Pasien'!$D:$D,300000)) | I4: =IF(C4="","",SUM(D4:H4)) | J4: =IF(C4="","",D4*100000) | K4: =IF(C4="","",E4*150000) | L4: =IF(C4="","",F4*200000) | M4: =IF(C4="","",G4*250000) | N4: =IF(C4="","",H4*300000) | O4: =IF(C4="","",SUM(J4:N4)) | P4: =IF(C4="","",D4*70000+E4*105000+F4*130000+G4*155000+H4*180000) | R4: =IF(C4="","",D4*30000+E4*45000+F4*70000+G4*95000+H4*120000)
A5: =IF(C5<>"",2,"") | D5: =IF(OR(B5="",C5=""),"",COUNTIFS('📋 Data Pasien'!$B:$B,B5,'📋 Data Pasien'!$J:$J,C5,'📋 Data Pasien'!$D:$D,100000)) | E5: =IF(OR(B5="",C5=""),"",COUNTIFS('📋 Data Pasien'!$B:$B,B5,'📋 Data Pasien'!$J:$J,C5,'📋 Data Pasien'!$D:$D,150000)) | F5: =IF(OR(B5="",C5=""),"",COUNTIFS('📋 Data Pasien'!$B:$B,B5,'📋 Data Pasien'!$J:$J,C5,'📋 Data Pasien'!$D:$D,200000)) | G5: =IF(OR(B5="",C5=""),"",COUNTIFS('📋 Data Pasien'!$B:$B,B5,'📋 Data Pasien'!$J:$J,C5,'📋 Data Pasien'!$D:$D,250000)) | H5: =IF(OR(B5="",C5=""),"",COUNTIFS('📋 Data Pasien'!$B:$B,B5,'📋 Data Pasien'!$J:$J,C5,'📋 Data Pasien'!$D:$D,300000)) | I5: =IF(C5="","",SUM(D5:H5)) | J5: =IF(C5="","",D5*100000) | K5: =IF(C5="","",E5*150000) | L5: =IF(C5="","",F5*200000) | M5: =IF(C5="","",G5*250000) | N5: =IF(C5="","",H5*300000) | O5: =IF(C5="","",SUM(J5:N5)) | P5: =IF(C5="","",D5*70000+E5*105000+F5*130000+G5*155000+H5*180000) | R5: =IF(C5="","",D5*30000+E5*45000+F5*70000+G5*95000+H5*120000)
A6: =IF(C6<>"",3,"") | D6: =IF(OR(B6="",C6=""),"",COUNTIFS('📋 Data Pasien'!$B:$B,B6,'📋 Data Pasien'!$J:$J,C6,'📋 Data Pasien'!$D:$D,100000)) | E6: =IF(OR(B6="",C6=""),"",COUNTIFS('📋 Data Pasien'!$B:$B,B6,'📋 Data Pasien'!$J:$J,C6,'📋 Data Pasien'!$D:$D,150000)) | F6: =IF(OR(B6="",C6=""),"",COUNTIFS('📋 Data Pasien'!$B:$B,B6,'📋 Data Pasien'!$J:$J,C6,'📋 Data Pasien'!$D:$D,200000)) | G6: =IF(OR(B6="",C6=""),"",COUNTIFS('📋 Data Pasien'!$B:$B,B6,'📋 Data Pasien'!$J:$J,C6,'📋 Data Pasien'!$D:$D,250000)) | H6: =IF(OR(B6="",C6=""),"",COUNTIFS('📋 Data Pasien'!$B:$B,B6,'📋 Data Pasien'!$J:$J,C6,'📋 Data Pasien'!$D:$D,300000)) | I6: =IF(C6="","",SUM(D6:H6)) | J6: =IF(C6="","",D6*100000) | K6: =IF(C6="","",E6*150000) | L6: =IF(C6="","",F6*200000) | M6: =IF(C6="","",G6*250000) | N6: =IF(C6="","",H6*300000) | O6: =IF(C6="","",SUM(J6:N6)) | P6: =IF(C6="","",D6*70000+E6*105000+F6*130000+G6*155000+H6*180000) | R6: =IF(C6="","",D6*30000+E6*45000+F6*70000+G6*95000+H6*120000)
A7: =IF(C7<>"",4,"") | D7: =IF(OR(B7="",C7=""),"",COUNTIFS('📋 Data Pasien'!$B:$B,B7,'📋 Data Pasien'!$J:$J,C7,'📋 Data Pasien'!$D:$D,100000)) | E7: =IF(OR(B7="",C7=""),"",COUNTIFS('📋 Data Pasien'!$B:$B,B7,'📋 Data Pasien'!$J:$J,C7,'📋 Data Pasien'!$D:$D,150000)) | F7: =IF(OR(B7="",C7=""),"",COUNTIFS('📋 Data Pasien'!$B:$B,B7,'📋 Data Pasien'!$J:$J,C7,'📋 Data Pasien'!$D:$D,200000)) | G7: =IF(OR(B7="",C7=""),"",COUNTIFS('📋 Data Pasien'!$B:$B,B7,'📋 Data Pasien'!$J:$J,C7,'📋 Data Pasien'!$D:$D,250000)) | H7: =IF(OR(B7="",C7=""),"",COUNTIFS('📋 Data Pasien'!$B:$B,B7,'📋 Data Pasien'!$J:$J,C7,'📋 Data Pasien'!$D:$D,300000)) | I7: =IF(C7="","",SUM(D7:H7)) | J7: =IF(C7="","",D7*100000) | K7: =IF(C7="","",E7*150000) | L7: =IF(C7="","",F7*200000) | M7: =IF(C7="","",G7*250000) | N7: =IF(C7="","",H7*300000) | O7: =IF(C7="","",SUM(J7:N7)) | P7: =IF(C7="","",D7*70000+E7*105000+F7*130000+G7*155000+H7*180000) | R7: =IF(C7="","",D7*30000+E7*45000+F7*70000+G7*95000+H7*120000)
A8: =IF(C8<>"",5,"") | D8: =IF(OR(B8="",C8=""),"",COUNTIFS('📋 Data Pasien'!$B:$B,B8,'📋 Data Pasien'!$J:$J,C8,'📋 Data Pasien'!$D:$D,100000)) | E8: =IF(OR(B8="",C8=""),"",COUNTIFS('📋 Data Pasien'!$B:$B,B8,'📋 Data Pasien'!$J:$J,C8,'📋 Data Pasien'!$D:$D,150000)) | F8: =IF(OR(B8="",C8=""),"",COUNTIFS('📋 Data Pasien'!$B:$B,B8,'📋 Data Pasien'!$J:$J,C8,'📋 Data Pasien'!$D:$D,200000)) | G8: =IF(OR(B8="",C8=""),"",COUNTIFS('📋 Data Pasien'!$B:$B,B8,'📋 Data Pasien'!$J:$J,C8,'📋 Data Pasien'!$D:$D,250000)) | H8: =IF(OR(B8="",C8=""),"",COUNTIFS('📋 Data Pasien'!$B:$B,B8,'📋 Data Pasien'!$J:$J,C8,'📋 Data Pasien'!$D:$D,300000)) | I8: =IF(C8="","",SUM(D8:H8)) | J8: =IF(C8="","",D8*100000) | K8: =IF(C8="","",E8*150000) | L8: =IF(C8="","",F8*200000) | M8: =IF(C8="","",G8*250000) | N8: =IF(C8="","",H8*300000) | O8: =IF(C8="","",SUM(J8:N8)) | P8: =IF(C8="","",D8*70000+E8*105000+F8*130000+G8*155000+H8*180000) | R8: =IF(C8="","",D8*30000+E8*45000+F8*70000+G8*95000+H8*120000)
A9: =IF(C9<>"",6,"") | D9: =IF(OR(B9="",C9=""),"",COUNTIFS('📋 Data Pasien'!$B:$B,B9,'📋 Data Pasien'!$J:$J,C9,'📋 Data Pasien'!$D:$D,100000)) | E9: =IF(OR(B9="",C9=""),"",COUNTIFS('📋 Data Pasien'!$B:$B,B9,'📋 Data Pasien'!$J:$J,C9,'📋 Data Pasien'!$D:$D,150000)) | F9: =IF(OR(B9="",C9=""),"",COUNTIFS('📋 Data Pasien'!$B:$B,B9,'📋 Data Pasien'!$J:$J,C9,'📋 Data Pasien'!$D:$D,200000)) | G9: =IF(OR(B9="",C9=""),"",COUNTIFS('📋 Data Pasien'!$B:$B,B9,'📋 Data Pasien'!$J:$J,C9,'📋 Data Pasien'!$D:$D,250000)) | H9: =IF(OR(B9="",C9=""),"",COUNTIFS('📋 Data Pasien'!$B:$B,B9,'📋 Data Pasien'!$J:$J,C9,'📋 Data Pasien'!$D:$D,300000)) | I9: =IF(C9="","",SUM(D9:H9)) | J9: =IF(C9="","",D9*100000) | K9: =IF(C9="","",E9*150000) | L9: =IF(C9="","",F9*200000) | M9: =IF(C9="","",G9*250000) | N9: =IF(C9="","",H9*300000) | O9: =IF(C9="","",SUM(J9:N9)) | P9: =IF(C9="","",D9*70000+E9*105000+F9*130000+G9*155000+H9*180000) | R9: =IF(C9="","",D9*30000+E9*45000+F9*70000+G9*95000+H9*120000)
A10: =IF(C10<>"",7,"") | D10: =IF(OR(B10="",C10=""),"",COUNTIFS('📋 Data Pasien'!$B:$B,B10,'📋 Data Pasien'!$J:$J,C10,'📋 Data Pasien'!$D:$D,100000)) | E10: =IF(OR(B10="",C10=""),"",COUNTIFS('📋 Data Pasien'!$B:$B,B10,'📋 Data Pasien'!$J:$J,C10,'📋 Data Pasien'!$D:$D,150000)) | F10: =IF(OR(B10="",C10=""),"",COUNTIFS('📋 Data Pasien'!$B:$B,B10,'📋 Data Pasien'!$J:$J,C10,'📋 Data Pasien'!$D:$D,200000)) | G10: =IF(OR(B10="",C10=""),"",COUNTIFS('📋 Data Pasien'!$B:$B,B10,'📋 Data Pasien'!$J:$J,C10,'📋 Data Pasien'!$D:$D,250000)) | H10: =IF(OR(B10="",C10=""),"",COUNTIFS('📋 Data Pasien'!$B:$B,B10,'📋 Data Pasien'!$J:$J,C10,'📋 Data Pasien'!$D:$D,300000)) | I10: =IF(C10="","",SUM(D10:H10)) | J10: =IF(C10="","",D10*100000) | K10: =IF(C10="","",E10*150000) | L10: =IF(C10="","",F10*200000) | M10: =IF(C10="","",G10*250000) | N10: =IF(C10="","",H10*300000) | O10: =IF(C10="","",SUM(J10:N10)) | P10: =IF(C10="","",D10*70000+E10*105000+F10*130000+G10*155000+H10*180000) | R10: =IF(C10="","",D10*30000+E10*45000+F10*70000+G10*95000+H10*120000)
A11: =IF(C11<>"",8,"") | D11: =IF(OR(B11="",C11=""),"",COUNTIFS('📋 Data Pasien'!$B:$B,B11,'📋 Data Pasien'!$J:$J,C11,'📋 Data Pasien'!$D:$D,100000)) | E11: =IF(OR(B11="",C11=""),"",COUNTIFS('📋 Data Pasien'!$B:$B,B11,'📋 Data Pasien'!$J:$J,C11,'📋 Data Pasien'!$D:$D,150000)) | F11: =IF(OR(B11="",C11=""),"",COUNTIFS('📋 Data Pasien'!$B:$B,B11,'📋 Data Pasien'!$J:$J,C11,'📋 Data Pasien'!$D:$D,200000)) | G11: =IF(OR(B11="",C11=""),"",COUNTIFS('📋 Data Pasien'!$B:$B,B11,'📋 Data Pasien'!$J:$J,C11,'📋 Data Pasien'!$D:$D,250000)) | H11: =IF(OR(B11="",C11=""),"",COUNTIFS('📋 Data Pasien'!$B:$B,B11,'📋 Data Pasien'!$J:$J,C11,'📋 Data Pasien'!$D:$D,300000)) | I11: =IF(C11="","",SUM(D11:H11)) | J11: =IF(C11="","",D11*100000) | K11: =IF(C11="","",E11*150000) | L11: =IF(C11="","",F11*200000) | M11: =IF(C11="","",G11*250000) | N11: =IF(C11="","",H11*300000) | O11: =IF(C11="","",SUM(J11:N11)) | P11: =IF(C11="","",D11*70000+E11*105000+F11*130000+G11*155000+H11*180000) | R11: =IF(C11="","",D11*30000+E11*45000+F11*70000+G11*95000+H11*120000)
A12: =IF(C12<>"",9,"") | D12: =IF(OR(B12="",C12=""),"",COUNTIFS('📋 Data Pasien'!$B:$B,B12,'📋 Data Pasien'!$J:$J,C12,'📋 Data Pasien'!$D:$D,100000)) | E12: =IF(OR(B12="",C12=""),"",COUNTIFS('📋 Data Pasien'!$B:$B,B12,'📋 Data Pasien'!$J:$J,C12,'📋 Data Pasien'!$D:$D,150000)) | F12: =IF(OR(B12="",C12=""),"",COUNTIFS('📋 Data Pasien'!$B:$B,B12,'📋 Data Pasien'!$J:$J,C12,'📋 Data Pasien'!$D:$D,200000)) | G12: =IF(OR(B12="",C12=""),"",COUNTIFS('📋 Data Pasien'!$B:$B,B12,'📋 Data Pasien'!$J:$J,C12,'📋 Data Pasien'!$D:$D,250000)) | H12: =IF(OR(B12="",C12=""),"",COUNTIFS('📋 Data Pasien'!$B:$B,B12,'📋 Data Pasien'!$J:$J,C12,'📋 Data Pasien'!$D:$D,300000)) | I12: =IF(C12="","",SUM(D12:H12)) | J12: =IF(C12="","",D12*100000) | K12: =IF(C12="","",E12*150000) | L12: =IF(C12="","",F12*200000) | M12: =IF(C12="","",G12*250000) | N12: =IF(C12="","",H12*300000) | O12: =IF(C12="","",SUM(J12:N12)) | P12: =IF(C12="","",D12*70000+E12*105000+F12*130000+G12*155000+H12*180000) | R12: =IF(C12="","",D12*30000+E12*45000+F12*70000+G12*95000+H12*120000)
A13: =IF(C13<>"",10,"") | D13: =IF(OR(B13="",C13=""),"",COUNTIFS('📋 Data Pasien'!$B:$B,B13,'📋 Data Pasien'!$J:$J,C13,'📋 Data Pasien'!$D:$D,100000)) | E13: =IF(OR(B13="",C13=""),"",COUNTIFS('📋 Data Pasien'!$B:$B,B13,'📋 Data Pasien'!$J:$J,C13,'📋 Data Pasien'!$D:$D,150000)) | F13: =IF(OR(B13="",C13=""),"",COUNTIFS('📋 Data Pasien'!$B:$B,B13,'📋 Data Pasien'!$J:$J,C13,'📋 Data Pasien'!$D:$D,200000)) | G13: =IF(OR(B13="",C13=""),"",COUNTIFS('📋 Data Pasien'!$B:$B,B13,'📋 Data Pasien'!$J:$J,C13,'📋 Data Pasien'!$D:$D,250000)) | H13: =IF(OR(B13="",C13=""),"",COUNTIFS('📋 Data Pasien'!$B:$B,B13,'📋 Data Pasien'!$J:$J,C13,'📋 Data Pasien'!$D:$D,300000)) | I13: =IF(C13="","",SUM(D13:H13)) | J13: =IF(C13="","",D13*100000) | K13: =IF(C13="","",E13*150000) | L13: =IF(C13="","",F13*200000) | M13: =IF(C13="","",G13*250000) | N13: =IF(C13="","",H13*300000) | O13: =IF(C13="","",SUM(J13:N13)) | P13: =IF(C13="","",D13*70000+E13*105000+F13*130000+G13*155000+H13*180000) | R13: =IF(C13="","",D13*30000+E13*45000+F13*70000+G13*95000+H13*120000)
A14: =IF(C14<>"",11,"") | D14: =IF(OR(B14="",C14=""),"",COUNTIFS('📋 Data Pasien'!$B:$B,B14,'📋 Data Pasien'!$J:$J,C14,'📋 Data Pasien'!$D:$D,100000)) | E14: =IF(OR(B14="",C14=""),"",COUNTIFS('📋 Data Pasien'!$B:$B,B14,'📋 Data Pasien'!$J:$J,C14,'📋 Data Pasien'!$D:$D,150000)) | F14: =IF(OR(B14="",C14=""),"",COUNTIFS('📋 Data Pasien'!$B:$B,B14,'📋 Data Pasien'!$J:$J,C14,'📋 Data Pasien'!$D:$D,200000)) | G14: =IF(OR(B14="",C14=""),"",COUNTIFS('📋 Data Pasien'!$B:$B,B14,'📋 Data Pasien'!$J:$J,C14,'📋 Data Pasien'!$D:$D,250000)) | H14: =IF(OR(B14="",C14=""),"",COUNTIFS('📋 Data Pasien'!$B:$B,B14,'📋 Data Pasien'!$J:$J,C14,'📋 Data Pasien'!$D:$D,300000)) | I14: =IF(C14="","",SUM(D14:H14)) | J14: =IF(C14="","",D14*100000) | K14: =IF(C14="","",E14*150000) | L14: =IF(C14="","",F14*200000) | M14: =IF(C14="","",G14*250000) | N14: =IF(C14="","",H14*300000) | O14: =IF(C14="","",SUM(J14:N14)) | P14: =IF(C14="","",D14*70000+E14*105000+F14*130000+G14*155000+H14*180000) | R14: =IF(C14="","",D14*30000+E14*45000+F14*70000+G14*95000+H14*120000)
A15: =IF(C15<>"",12,"") | D15: =IF(OR(B15="",C15=""),"",COUNTIFS('📋 Data Pasien'!$B:$B,B15,'📋 Data Pasien'!$J:$J,C15,'📋 Data Pasien'!$D:$D,100000)) | E15: =IF(OR(B15="",C15=""),"",COUNTIFS('📋 Data Pasien'!$B:$B,B15,'📋 Data Pasien'!$J:$J,C15,'📋 Data Pasien'!$D:$D,150000)) | F15: =IF(OR(B15="",C15=""),"",COUNTIFS('📋 Data Pasien'!$B:$B,B15,'📋 Data Pasien'!$J:$J,C15,'📋 Data Pasien'!$D:$D,200000)) | G15: =IF(OR(B15="",C15=""),"",COUNTIFS('📋 Data Pasien'!$B:$B,B15,'📋 Data Pasien'!$J:$J,C15,'📋 Data Pasien'!$D:$D,250000)) | H15: =IF(OR(B15="",C15=""),"",COUNTIFS('📋 Data Pasien'!$B:$B,B15,'📋 Data Pasien'!$J:$J,C15,'📋 Data Pasien'!$D:$D,300000)) | I15: =IF(C15="","",SUM(D15:H15)) | J15: =IF(C15="","",D15*100000) | K15: =IF(C15="","",E15*150000) | L15: =IF(C15="","",F15*200000) | M15: =IF(C15="","",G15*250000) | N15: =IF(C15="","",H15*300000) | O15: =IF(C15="","",SUM(J15:N15)) | P15: =IF(C15="","",D15*70000+E15*105000+F15*130000+G15*155000+H15*180000) | R15: =IF(C15="","",D15*30000+E15*45000+F15*70000+G15*95000+H15*120000)
A16: =IF(C16<>"",13,"") | D16: =IF(OR(B16="",C16=""),"",COUNTIFS('📋 Data Pasien'!$B:$B,B16,'📋 Data Pasien'!$J:$J,C16,'📋 Data Pasien'!$D:$D,100000)) | E16: =IF(OR(B16="",C16=""),"",COUNTIFS('📋 Data Pasien'!$B:$B,B16,'📋 Data Pasien'!$J:$J,C16,'📋 Data Pasien'!$D:$D,150000)) | F16: =IF(OR(B16="",C16=""),"",COUNTIFS('📋 Data Pasien'!$B:$B,B16,'📋 Data Pasien'!$J:$J,C16,'📋 Data Pasien'!$D:$D,200000)) | G16: =IF(OR(B16="",C16=""),"",COUNTIFS('📋 Data Pasien'!$B:$B,B16,'📋 Data Pasien'!$J:$J,C16,'📋 Data Pasien'!$D:$D,250000)) | H16: =IF(OR(B16="",C16=""),"",COUNTIFS('📋 Data Pasien'!$B:$B,B16,'📋 Data Pasien'!$J:$J,C16,'📋 Data Pasien'!$D:$D,300000)) | I16: =IF(C16="","",SUM(D16:H16)) | J16: =IF(C16="","",D16*100000) | K16: =IF(C16="","",E16*150000) | L16: =IF(C16="","",F16*200000) | M16: =IF(C16="","",G16*250000) | N16: =IF(C16="","",H16*300000) | O16: =IF(C16="","",SUM(J16:N16)) | P16: =IF(C16="","",D16*70000+E16*105000+F16*130000+G16*155000+H16*180000) | R16: =IF(C16="","",D16*30000+E16*45000+F16*70000+G16*95000+H16*120000)
A17: =IF(C17<>"",14,"") | D17: =IF(OR(B17="",C17=""),"",COUNTIFS('📋 Data Pasien'!$B:$B,B17,'📋 Data Pasien'!$J:$J,C17,'📋 Data Pasien'!$D:$D,100000)) | E17: =IF(OR(B17="",C17=""),"",COUNTIFS('📋 Data Pasien'!$B:$B,B17,'📋 Data Pasien'!$J:$J,C17,'📋 Data Pasien'!$D:$D,150000)) | F17: =IF(OR(B17="",C17=""),"",COUNTIFS('📋 Data Pasien'!$B:$B,B17,'📋 Data Pasien'!$J:$J,C17,'📋 Data Pasien'!$D:$D,200000)) | G17: =IF(OR(B17="",C17=""),"",COUNTIFS('📋 Data Pasien'!$B:$B,B17,'📋 Data Pasien'!$J:$J,C17,'📋 Data Pasien'!$D:$D,250000)) | H17: =IF(OR(B17="",C17=""),"",COUNTIFS('📋 Data Pasien'!$B:$B,B17,'📋 Data Pasien'!$J:$J,C17,'📋 Data Pasien'!$D:$D,300000)) | I17: =IF(C17="","",SUM(D17:H17)) | J17: =IF(C17="","",D17*100000) | K17: =IF(C17="","",E17*150000) | L17: =IF(C17="","",F17*200000) | M17: =IF(C17="","",G17*250000) | N17: =IF(C17="","",H17*300000) | O17: =IF(C17="","",SUM(J17:N17)) | P17: =IF(C17="","",D17*70000+E17*105000+F17*130000+G17*155000+H17*180000) | R17: =IF(C17="","",D17*30000+E17*45000+F17*70000+G17*95000+H17*120000)
A18: =IF(C18<>"",15,"") | D18: =IF(OR(B18="",C18=""),"",COUNTIFS('📋 Data Pasien'!$B:$B,B18,'📋 Data Pasien'!$J:$J,C18,'📋 Data Pasien'!$D:$D,100000)) | E18: =IF(OR(B18="",C18=""),"",COUNTIFS('📋 Data Pasien'!$B:$B,B18,'📋 Data Pasien'!$J:$J,C18,'📋 Data Pasien'!$D:$D,150000)) | F18: =IF(OR(B18="",C18=""),"",COUNTIFS('📋 Data Pasien'!$B:$B,B18,'📋 Data Pasien'!$J:$J,C18,'📋 Data Pasien'!$D:$D,200000)) | G18: =IF(OR(B18="",C18=""),"",COUNTIFS('📋 Data Pasien'!$B:$B,B18,'📋 Data Pasien'!$J:$J,C18,'📋 Data Pasien'!$D:$D,250000)) | H18: =IF(OR(B18="",C18=""),"",COUNTIFS('📋 Data Pasien'!$B:$B,B18,'📋 Data Pasien'!$J:$J,C18,'📋 Data Pasien'!$D:$D,300000)) | I18: =IF(C18="","",SUM(D18:H18)) | J18: =IF(C18="","",D18*100000) | K18: =IF(C18="","",E18*150000) | L18: =IF(C18="","",F18*200000) | M18: =IF(C18="","",G18*250000) | N18: =IF(C18="","",H18*300000) | O18: =IF(C18="","",SUM(J18:N18)) | P18: =IF(C18="","",D18*70000+E18*105000+F18*130000+G18*155000+H18*180000) | R18: =IF(C18="","",D18*30000+E18*45000+F18*70000+G18*95000+H18*120000)
A19: =IF(C19<>"",16,"") | D19: =IF(OR(B19="",C19=""),"",COUNTIFS('📋 Data Pasien'!$B:$B,B19,'📋 Data Pasien'!$J:$J,C19,'📋 Data Pasien'!$D:$D,100000)) | E19: =IF(OR(B19="",C19=""),"",COUNTIFS('📋 Data Pasien'!$B:$B,B19,'📋 Data Pasien'!$J:$J,C19,'📋 Data Pasien'!$D:$D,150000)) | F19: =IF(OR(B19="",C19=""),"",COUNTIFS('📋 Data Pasien'!$B:$B,B19,'📋 Data Pasien'!$J:$J,C19,'📋 Data Pasien'!$D:$D,200000)) | G19: =IF(OR(B19="",C19=""),"",COUNTIFS('📋 Data Pasien'!$B:$B,B19,'📋 Data Pasien'!$J:$J,C19,'📋 Data Pasien'!$D:$D,250000)) | H19: =IF(OR(B19="",C19=""),"",COUNTIFS('📋 Data Pasien'!$B:$B,B19,'📋 Data Pasien'!$J:$J,C19,'📋 Data Pasien'!$D:$D,300000)) | I19: =IF(C19="","",SUM(D19:H19)) | J19: =IF(C19="","",D19*100000) | K19: =IF(C19="","",E19*150000) | L19: =IF(C19="","",F19*200000) | M19: =IF(C19="","",G19*250000) | N19: =IF(C19="","",H19*300000) | O19: =IF(C19="","",SUM(J19:N19)) | P19: =IF(C19="","",D19*70000+E19*105000+F19*130000+G19*155000+H19*180000) | R19: =IF(C19="","",D19*30000+E19*45000+F19*70000+G19*95000+H19*120000)
A20: =IF(C20<>"",17,"") | D20: =IF(OR(B20="",C20=""),"",COUNTIFS('📋 Data Pasien'!$B:$B,B20,'📋 Data Pasien'!$J:$J,C20,'📋 Data Pasien'!$D:$D,100000)) | E20: =IF(OR(B20="",C20=""),"",COUNTIFS('📋 Data Pasien'!$B:$B,B20,'📋 Data Pasien'!$J:$J,C20,'📋 Data Pasien'!$D:$D,150000)) | F20: =IF(OR(B20="",C20=""),"",COUNTIFS('📋 Data Pasien'!$B:$B,B20,'📋 Data Pasien'!$J:$J,C20,'📋 Data Pasien'!$D:$D,200000)) | G20: =IF(OR(B20="",C20=""),"",COUNTIFS('📋 Data Pasien'!$B:$B,B20,'📋 Data Pasien'!$J:$J,C20,'📋 Data Pasien'!$D:$D,250000)) | H20: =IF(OR(B20="",C20=""),"",COUNTIFS('📋 Data Pasien'!$B:$B,B20,'📋 Data Pasien'!$J:$J,C20,'📋 Data Pasien'!$D:$D,300000)) | I20: =IF(C20="","",SUM(D20:H20)) | J20: =IF(C20="","",D20*100000) | K20: =IF(C20="","",E20*150000) | L20: =IF(C20="","",F20*200000) | M20: =IF(C20="","",G20*250000) | N20: =IF(C20="","",H20*300000) | O20: =IF(C20="","",SUM(J20:N20)) | P20: =IF(C20="","",D20*70000+E20*105000+F20*130000+G20*155000+H20*180000) | R20: =IF(C20="","",D20*30000+E20*45000+F20*70000+G20*95000+H20*120000)
A21: =IF(C21<>"",18,"") | D21: =IF(OR(B21="",C21=""),"",COUNTIFS('📋 Data Pasien'!$B:$B,B21,'📋 Data Pasien'!$J:$J,C21,'📋 Data Pasien'!$D:$D,100000)) | E21: =IF(OR(B21="",C21=""),"",COUNTIFS('📋 Data Pasien'!$B:$B,B21,'📋 Data Pasien'!$J:$J,C21,'📋 Data Pasien'!$D:$D,150000)) | F21: =IF(OR(B21="",C21=""),"",COUNTIFS('📋 Data Pasien'!$B:$B,B21,'📋 Data Pasien'!$J:$J,C21,'📋 Data Pasien'!$D:$D,200000)) | G21: =IF(OR(B21="",C21=""),"",COUNTIFS('📋 Data Pasien'!$B:$B,B21,'📋 Data Pasien'!$J:$J,C21,'📋 Data Pasien'!$D:$D,250000)) | H21: =IF(OR(B21="",C21=""),"",COUNTIFS('📋 Data Pasien'!$B:$B,B21,'📋 Data Pasien'!$J:$J,C21,'📋 Data Pasien'!$D:$D,300000)) | I21: =IF(C21="","",SUM(D21:H21)) | J21: =IF(C21="","",D21*100000) | K21: =IF(C21="","",E21*150000) | L21: =IF(C21="","",F21*200000) | M21: =IF(C21="","",G21*250000) | N21: =IF(C21="","",H21*300000) | O21: =IF(C21="","",SUM(J21:N21)) | P21: =IF(C21="","",D21*70000+E21*105000+F21*130000+G21*155000+H21*180000) | R21: =IF(C21="","",D21*30000+E21*45000+F21*70000+G21*95000+H21*120000)
A22: =IF(C22<>"",19,"") | D22: =IF(OR(B22="",C22=""),"",COUNTIFS('📋 Data Pasien'!$B:$B,B22,'📋 Data Pasien'!$J:$J,C22,'📋 Data Pasien'!$D:$D,100000)) | E22: =IF(OR(B22="",C22=""),"",COUNTIFS('📋 Data Pasien'!$B:$B,B22,'📋 Data Pasien'!$J:$J,C22,'📋 Data Pasien'!$D:$D,150000)) | F22: =IF(OR(B22="",C22=""),"",COUNTIFS('📋 Data Pasien'!$B:$B,B22,'📋 Data Pasien'!$J:$J,C22,'📋 Data Pasien'!$D:$D,200000)) | G22: =IF(OR(B22="",C22=""),"",COUNTIFS('📋 Data Pasien'!$B:$B,B22,'📋 Data Pasien'!$J:$J,C22,'📋 Data Pasien'!$D:$D,250000)) | H22: =IF(OR(B22="",C22=""),"",COUNTIFS('📋 Data Pasien'!$B:$B,B22,'📋 Data Pasien'!$J:$J,C22,'📋 Data Pasien'!$D:$D,300000)) | I22: =IF(C22="","",SUM(D22:H22)) | J22: =IF(C22="","",D22*100000) | K22: =IF(C22="","",E22*150000) | L22: =IF(C22="","",F22*200000) | M22: =IF(C22="","",G22*250000) | N22: =IF(C22="","",H22*300000) | O22: =IF(C22="","",SUM(J22:N22)) | P22: =IF(C22="","",D22*70000+E22*105000+F22*130000+G22*155000+H22*180000) | R22: =IF(C22="","",D22*30000+E22*45000+F22*70000+G22*95000+H22*120000)
A23: =IF(C23<>"",20,"") | D23: =IF(OR(B23="",C23=""),"",COUNTIFS('📋 Data Pasien'!$B:$B,B23,'📋 Data Pasien'!$J:$J,C23,'📋 Data Pasien'!$D:$D,100000)) | E23: =IF(OR(B23="",C23=""),"",COUNTIFS('📋 Data Pasien'!$B:$B,B23,'📋 Data Pasien'!$J:$J,C23,'📋 Data Pasien'!$D:$D,150000)) | F23: =IF(OR(B23="",C23=""),"",COUNTIFS('📋 Data Pasien'!$B:$B,B23,'📋 Data Pasien'!$J:$J,C23,'📋 Data Pasien'!$D:$D,200000)) | G23: =IF(OR(B23="",C23=""),"",COUNTIFS('📋 Data Pasien'!$B:$B,B23,'📋 Data Pasien'!$J:$J,C23,'📋 Data Pasien'!$D:$D,250000)) | H23: =IF(OR(B23="",C23=""),"",COUNTIFS('📋 Data Pasien'!$B:$B,B23,'📋 Data Pasien'!$J:$J,C23,'📋 Data Pasien'!$D:$D,300000)) | I23: =IF(C23="","",SUM(D23:H23)) | J23: =IF(C23="","",D23*100000) | K23: =IF(C23="","",E23*150000) | L23: =IF(C23="","",F23*200000) | M23: =IF(C23="","",G23*250000) | N23: =IF(C23="","",H23*300000) | O23: =IF(C23="","",SUM(J23:N23)) | P23: =IF(C23="","",D23*70000+E23*105000+F23*130000+G23*155000+H23*180000) | R23: =IF(C23="","",D23*30000+E23*45000+F23*70000+G23*95000+H23*120000)
A24: =IF(C24<>"",21,"") | D24: =IF(OR(B24="",C24=""),"",COUNTIFS('📋 Data Pasien'!$B:$B,B24,'📋 Data Pasien'!$J:$J,C24,'📋 Data Pasien'!$D:$D,100000)) | E24: =IF(OR(B24="",C24=""),"",COUNTIFS('📋 Data Pasien'!$B:$B,B24,'📋 Data Pasien'!$J:$J,C24,'📋 Data Pasien'!$D:$D,150000)) | F24: =IF(OR(B24="",C24=""),"",COUNTIFS('📋 Data Pasien'!$B:$B,B24,'📋 Data Pasien'!$J:$J,C24,'📋 Data Pasien'!$D:$D,200000)) | G24: =IF(OR(B24="",C24=""),"",COUNTIFS('📋 Data Pasien'!$B:$B,B24,'📋 Data Pasien'!$J:$J,C24,'📋 Data Pasien'!$D:$D,250000)) | H24: =IF(OR(B24="",C24=""),"",COUNTIFS('📋 Data Pasien'!$B:$B,B24,'📋 Data Pasien'!$J:$J,C24,'📋 Data Pasien'!$D:$D,300000)) | I24: =IF(C24="","",SUM(D24:H24)) | J24: =IF(C24="","",D24*100000) | K24: =IF(C24="","",E24*150000) | L24: =IF(C24="","",F24*200000) | M24: =IF(C24="","",G24*250000) | N24: =IF(C24="","",H24*300000) | O24: =IF(C24="","",SUM(J24:N24)) | P24: =IF(C24="","",D24*70000+E24*105000+F24*130000+G24*155000+H24*180000) | R24: =IF(C24="","",D24*30000+E24*45000+F24*70000+G24*95000+H24*120000)
A25: =IF(C25<>"",22,"") | D25: =IF(OR(B25="",C25=""),"",COUNTIFS('📋 Data Pasien'!$B:$B,B25,'📋 Data Pasien'!$J:$J,C25,'📋 Data Pasien'!$D:$D,100000)) | E25: =IF(OR(B25="",C25=""),"",COUNTIFS('📋 Data Pasien'!$B:$B,B25,'📋 Data Pasien'!$J:$J,C25,'📋 Data Pasien'!$D:$D,150000)) | F25: =IF(OR(B25="",C25=""),"",COUNTIFS('📋 Data Pasien'!$B:$B,B25,'📋 Data Pasien'!$J:$J,C25,'📋 Data Pasien'!$D:$D,200000)) | G25: =IF(OR(B25="",C25=""),"",COUNTIFS('📋 Data Pasien'!$B:$B,B25,'📋 Data Pasien'!$J:$J,C25,'📋 Data Pasien'!$D:$D,250000)) | H25: =IF(OR(B25="",C25=""),"",COUNTIFS('📋 Data Pasien'!$B:$B,B25,'📋 Data Pasien'!$J:$J,C25,'📋 Data Pasien'!$D:$D,300000)) | I25: =IF(C25="","",SUM(D25:H25)) | J25: =IF(C25="","",D25*100000) | K25: =IF(C25="","",E25*150000) | L25: =IF(C25="","",F25*200000) | M25: =IF(C25="","",G25*250000) | N25: =IF(C25="","",H25*300000) | O25: =IF(C25="","",SUM(J25:N25)) | P25: =IF(C25="","",D25*70000+E25*105000+F25*130000+G25*155000+H25*180000) | R25: =IF(C25="","",D25*30000+E25*45000+F25*70000+G25*95000+H25*120000)
A26: =IF(C26<>"",23,"") | D26: =IF(OR(B26="",C26=""),"",COUNTIFS('📋 Data Pasien'!$B:$B,B26,'📋 Data Pasien'!$J:$J,C26,'📋 Data Pasien'!$D:$D,100000)) | E26: =IF(OR(B26="",C26=""),"",COUNTIFS('📋 Data Pasien'!$B:$B,B26,'📋 Data Pasien'!$J:$J,C26,'📋 Data Pasien'!$D:$D,150000)) | F26: =IF(OR(B26="",C26=""),"",COUNTIFS('📋 Data Pasien'!$B:$B,B26,'📋 Data Pasien'!$J:$J,C26,'📋 Data Pasien'!$D:$D,200000)) | G26: =IF(OR(B26="",C26=""),"",COUNTIFS('📋 Data Pasien'!$B:$B,B26,'📋 Data Pasien'!$J:$J,C26,'📋 Data Pasien'!$D:$D,250000)) | H26: =IF(OR(B26="",C26=""),"",COUNTIFS('📋 Data Pasien'!$B:$B,B26,'📋 Data Pasien'!$J:$J,C26,'📋 Data Pasien'!$D:$D,300000)) | I26: =IF(C26="","",SUM(D26:H26)) | J26: =IF(C26="","",D26*100000) | K26: =IF(C26="","",E26*150000) | L26: =IF(C26="","",F26*200000) | M26: =IF(C26="","",G26*250000) | N26: =IF(C26="","",H26*300000) | O26: =IF(C26="","",SUM(J26:N26)) | P26: =IF(C26="","",D26*70000+E26*105000+F26*130000+G26*155000+H26*180000) | R26: =IF(C26="","",D26*30000+E26*45000+F26*70000+G26*95000+H26*120000)
A27: =IF(C27<>"",24,"") | D27: =IF(OR(B27="",C27=""),"",COUNTIFS('📋 Data Pasien'!$B:$B,B27,'📋 Data Pasien'!$J:$J,C27,'📋 Data Pasien'!$D:$D,100000)) | E27: =IF(OR(B27="",C27=""),"",COUNTIFS('📋 Data Pasien'!$B:$B,B27,'📋 Data Pasien'!$J:$J,C27,'📋 Data Pasien'!$D:$D,150000)) | F27: =IF(OR(B27="",C27=""),"",COUNTIFS('📋 Data Pasien'!$B:$B,B27,'📋 Data Pasien'!$J:$J,C27,'📋 Data Pasien'!$D:$D,200000)) | G27: =IF(OR(B27="",C27=""),"",COUNTIFS('📋 Data Pasien'!$B:$B,B27,'📋 Data Pasien'!$J:$J,C27,'📋 Data Pasien'!$D:$D,250000)) | H27: =IF(OR(B27="",C27=""),"",COUNTIFS('📋 Data Pasien'!$B:$B,B27,'📋 Data Pasien'!$J:$J,C27,'📋 Data Pasien'!$D:$D,300000)) | I27: =IF(C27="","",SUM(D27:H27)) | J27: =IF(C27="","",D27*100000) | K27: =IF(C27="","",E27*150000) | L27: =IF(C27="","",F27*200000) | M27: =IF(C27="","",G27*250000) | N27: =IF(C27="","",H27*300000) | O27: =IF(C27="","",SUM(J27:N27)) | P27: =IF(C27="","",D27*70000+E27*105000+F27*130000+G27*155000+H27*180000) | R27: =IF(C27="","",D27*30000+E27*45000+F27*70000+G27*95000+H27*120000)
A28: =IF(C28<>"",25,"") | D28: =IF(OR(B28="",C28=""),"",COUNTIFS('📋 Data Pasien'!$B:$B,B28,'📋 Data Pasien'!$J:$J,C28,'📋 Data Pasien'!$D:$D,100000)) | E28: =IF(OR(B28="",C28=""),"",COUNTIFS('📋 Data Pasien'!$B:$B,B28,'📋 Data Pasien'!$J:$J,C28,'📋 Data Pasien'!$D:$D,150000)) | F28: =IF(OR(B28="",C28=""),"",COUNTIFS('📋 Data Pasien'!$B:$B,B28,'📋 Data Pasien'!$J:$J,C28,'📋 Data Pasien'!$D:$D,200000)) | G28: =IF(OR(B28="",C28=""),"",COUNTIFS('📋 Data Pasien'!$B:$B,B28,'📋 Data Pasien'!$J:$J,C28,'📋 Data Pasien'!$D:$D,250000)) | H28: =IF(OR(B28="",C28=""),"",COUNTIFS('📋 Data Pasien'!$B:$B,B28,'📋 Data Pasien'!$J:$J,C28,'📋 Data Pasien'!$D:$D,300000)) | I28: =IF(C28="","",SUM(D28:H28)) | J28: =IF(C28="","",D28*100000) | K28: =IF(C28="","",E28*150000) | L28: =IF(C28="","",F28*200000) | M28: =IF(C28="","",G28*250000) | N28: =IF(C28="","",H28*300000) | O28: =IF(C28="","",SUM(J28:N28)) | P28: =IF(C28="","",D28*70000+E28*105000+F28*130000+G28*155000+H28*180000) | R28: =IF(C28="","",D28*30000+E28*45000+F28*70000+G28*95000+H28*120000)
A29: =IF(C29<>"",26,"") | D29: =IF(OR(B29="",C29=""),"",COUNTIFS('📋 Data Pasien'!$B:$B,B29,'📋 Data Pasien'!$J:$J,C29,'📋 Data Pasien'!$D:$D,100000)) | E29: =IF(OR(B29="",C29=""),"",COUNTIFS('📋 Data Pasien'!$B:$B,B29,'📋 Data Pasien'!$J:$J,C29,'📋 Data Pasien'!$D:$D,150000)) | F29: =IF(OR(B29="",C29=""),"",COUNTIFS('📋 Data Pasien'!$B:$B,B29,'📋 Data Pasien'!$J:$J,C29,'📋 Data Pasien'!$D:$D,200000)) | G29: =IF(OR(B29="",C29=""),"",COUNTIFS('📋 Data Pasien'!$B:$B,B29,'📋 Data Pasien'!$J:$J,C29,'📋 Data Pasien'!$D:$D,250000)) | H29: =IF(OR(B29="",C29=""),"",COUNTIFS('📋 Data Pasien'!$B:$B,B29,'📋 Data Pasien'!$J:$J,C29,'📋 Data Pasien'!$D:$D,300000)) | I29: =IF(C29="","",SUM(D29:H29)) | J29: =IF(C29="","",D29*100000) | K29: =IF(C29="","",E29*150000) | L29: =IF(C29="","",F29*200000) | M29: =IF(C29="","",G29*250000) | N29: =IF(C29="","",H29*300000) | O29: =IF(C29="","",SUM(J29:N29)) | P29: =IF(C29="","",D29*70000+E29*105000+F29*130000+G29*155000+H29*180000) | R29: =IF(C29="","",D29*30000+E29*45000+F29*70000+G29*95000+H29*120000)
A30: =IF(C30<>"",27,"") | D30: =IF(OR(B30="",C30=""),"",COUNTIFS('📋 Data Pasien'!$B:$B,B30,'📋 Data Pasien'!$J:$J,C30,'📋 Data Pasien'!$D:$D,100000)) | E30: =IF(OR(B30="",C30=""),"",COUNTIFS('📋 Data Pasien'!$B:$B,B30,'📋 Data Pasien'!$J:$J,C30,'📋 Data Pasien'!$D:$D,150000)) | F30: =IF(OR(B30="",C30=""),"",COUNTIFS('📋 Data Pasien'!$B:$B,B30,'📋 Data Pasien'!$J:$J,C30,'📋 Data Pasien'!$D:$D,200000)) | G30: =IF(OR(B30="",C30=""),"",COUNTIFS('📋 Data Pasien'!$B:$B,B30,'📋 Data Pasien'!$J:$J,C30,'📋 Data Pasien'!$D:$D,250000)) | H30: =IF(OR(B30="",C30=""),"",COUNTIFS('📋 Data Pasien'!$B:$B,B30,'📋 Data Pasien'!$J:$J,C30,'📋 Data Pasien'!$D:$D,300000)) | I30: =IF(C30="","",SUM(D30:H30)) | J30: =IF(C30="","",D30*100000) | K30: =IF(C30="","",E30*150000) | L30: =IF(C30="","",F30*200000) | M30: =IF(C30="","",G30*250000) | N30: =IF(C30="","",H30*300000) | O30: =IF(C30="","",SUM(J30:N30)) | P30: =IF(C30="","",D30*70000+E30*105000+F30*130000+G30*155000+H30*180000) | R30: =IF(C30="","",D30*30000+E30*45000+F30*70000+G30*95000+H30*120000)
A31: =IF(C31<>"",28,"") | D31: =IF(OR(B31="",C31=""),"",COUNTIFS('📋 Data Pasien'!$B:$B,B31,'📋 Data Pasien'!$J:$J,C31,'📋 Data Pasien'!$D:$D,100000)) | E31: =IF(OR(B31="",C31=""),"",COUNTIFS('📋 Data Pasien'!$B:$B,B31,'📋 Data Pasien'!$J:$J,C31,'📋 Data Pasien'!$D:$D,150000)) | F31: =IF(OR(B31="",C31=""),"",COUNTIFS('📋 Data Pasien'!$B:$B,B31,'📋 Data Pasien'!$J:$J,C31,'📋 Data Pasien'!$D:$D,200000)) | G31: =IF(OR(B31="",C31=""),"",COUNTIFS('📋 Data Pasien'!$B:$B,B31,'📋 Data Pasien'!$J:$J,C31,'📋 Data Pasien'!$D:$D,250000)) | H31: =IF(OR(B31="",C31=""),"",COUNTIFS('📋 Data Pasien'!$B:$B,B31,'📋 Data Pasien'!$J:$J,C31,'📋 Data Pasien'!$D:$D,300000)) | I31: =IF(C31="","",SUM(D31:H31)) | J31: =IF(C31="","",D31*100000) | K31: =IF(C31="","",E31*150000) | L31: =IF(C31="","",F31*200000) | M31: =IF(C31="","",G31*250000) | N31: =IF(C31="","",H31*300000) | O31: =IF(C31="","",SUM(J31:N31)) | P31: =IF(C31="","",D31*70000+E31*105000+F31*130000+G31*155000+H31*180000) | R31: =IF(C31="","",D31*30000+E31*45000+F31*70000+G31*95000+H31*120000)
A32: =IF(C32<>"",29,"") | D32: =IF(OR(B32="",C32=""),"",COUNTIFS('📋 Data Pasien'!$B:$B,B32,'📋 Data Pasien'!$J:$J,C32,'📋 Data Pasien'!$D:$D,100000)) | E32: =IF(OR(B32="",C32=""),"",COUNTIFS('📋 Data Pasien'!$B:$B,B32,'📋 Data Pasien'!$J:$J,C32,'📋 Data Pasien'!$D:$D,150000)) | F32: =IF(OR(B32="",C32=""),"",COUNTIFS('📋 Data Pasien'!$B:$B,B32,'📋 Data Pasien'!$J:$J,C32,'📋 Data Pasien'!$D:$D,200000)) | G32: =IF(OR(B32="",C32=""),"",COUNTIFS('📋 Data Pasien'!$B:$B,B32,'📋 Data Pasien'!$J:$J,C32,'📋 Data Pasien'!$D:$D,250000)) | H32: =IF(OR(B32="",C32=""),"",COUNTIFS('📋 Data Pasien'!$B:$B,B32,'📋 Data Pasien'!$J:$J,C32,'📋 Data Pasien'!$D:$D,300000)) | I32: =IF(C32="","",SUM(D32:H32)) | J32: =IF(C32="","",D32*100000) | K32: =IF(C32="","",E32*150000) | L32: =IF(C32="","",F32*200000) | M32: =IF(C32="","",G32*250000) | N32: =IF(C32="","",H32*300000) | O32: =IF(C32="","",SUM(J32:N32)) | P32: =IF(C32="","",D32*70000+E32*105000+F32*130000+G32*155000+H32*180000) | R32: =IF(C32="","",D32*30000+E32*45000+F32*70000+G32*95000+H32*120000)
A33: =IF(C33<>"",30,"") | D33: =IF(OR(B33="",C33=""),"",COUNTIFS('📋 Data Pasien'!$B:$B,B33,'📋 Data Pasien'!$J:$J,C33,'📋 Data Pasien'!$D:$D,100000)) | E33: =IF(OR(B33="",C33=""),"",COUNTIFS('📋 Data Pasien'!$B:$B,B33,'📋 Data Pasien'!$J:$J,C33,'📋 Data Pasien'!$D:$D,150000)) | F33: =IF(OR(B33="",C33=""),"",COUNTIFS('📋 Data Pasien'!$B:$B,B33,'📋 Data Pasien'!$J:$J,C33,'📋 Data Pasien'!$D:$D,200000)) | G33: =IF(OR(B33="",C33=""),"",COUNTIFS('📋 Data Pasien'!$B:$B,B33,'📋 Data Pasien'!$J:$J,C33,'📋 Data Pasien'!$D:$D,250000)) | H33: =IF(OR(B33="",C33=""),"",COUNTIFS('📋 Data Pasien'!$B:$B,B33,'📋 Data Pasien'!$J:$J,C33,'📋 Data Pasien'!$D:$D,300000)) | I33: =IF(C33="","",SUM(D33:H33)) | J33: =IF(C33="","",D33*100000) | K33: =IF(C33="","",E33*150000) | L33: =IF(C33="","",F33*200000) | M33: =IF(C33="","",G33*250000) | N33: =IF(C33="","",H33*300000) | O33: =IF(C33="","",SUM(J33:N33)) | P33: =IF(C33="","",D33*70000+E33*105000+F33*130000+G33*155000+H33*180000) | R33: =IF(C33="","",D33*30000+E33*45000+F33*70000+G33*95000+H33*120000)
A34: =IF(C34<>"",31,"") | D34: =IF(OR(B34="",C34=""),"",COUNTIFS('📋 Data Pasien'!$B:$B,B34,'📋 Data Pasien'!$J:$J,C34,'📋 Data Pasien'!$D:$D,100000)) | E34: =IF(OR(B34="",C34=""),"",COUNTIFS('📋 Data Pasien'!$B:$B,B34,'📋 Data Pasien'!$J:$J,C34,'📋 Data Pasien'!$D:$D,150000)) | F34: =IF(OR(B34="",C34=""),"",COUNTIFS('📋 Data Pasien'!$B:$B,B34,'📋 Data Pasien'!$J:$J,C34,'📋 Data Pasien'!$D:$D,200000)) | G34: =IF(OR(B34="",C34=""),"",COUNTIFS('📋 Data Pasien'!$B:$B,B34,'📋 Data Pasien'!$J:$J,C34,'📋 Data Pasien'!$D:$D,250000)) | H34: =IF(OR(B34="",C34=""),"",COUNTIFS('📋 Data Pasien'!$B:$B,B34,'📋 Data Pasien'!$J:$J,C34,'📋 Data Pasien'!$D:$D,300000)) | I34: =IF(C34="","",SUM(D34:H34)) | J34: =IF(C34="","",D34*100000) | K34: =IF(C34="","",E34*150000) | L34: =IF(C34="","",F34*200000) | M34: =IF(C34="","",G34*250000) | N34: =IF(C34="","",H34*300000) | O34: =IF(C34="","",SUM(J34:N34)) | P34: =IF(C34="","",D34*70000+E34*105000+F34*130000+G34*155000+H34*180000) | R34: =IF(C34="","",D34*30000+E34*45000+F34*70000+G34*95000+H34*120000)
A35: =IF(C35<>"",32,"") | D35: =IF(OR(B35="",C35=""),"",COUNTIFS('📋 Data Pasien'!$B:$B,B35,'📋 Data Pasien'!$J:$J,C35,'📋 Data Pasien'!$D:$D,100000)) | E35: =IF(OR(B35="",C35=""),"",COUNTIFS('📋 Data Pasien'!$B:$B,B35,'📋 Data Pasien'!$J:$J,C35,'📋 Data Pasien'!$D:$D,150000)) | F35: =IF(OR(B35="",C35=""),"",COUNTIFS('📋 Data Pasien'!$B:$B,B35,'📋 Data Pasien'!$J:$J,C35,'📋 Data Pasien'!$D:$D,200000)) | G35: =IF(OR(B35="",C35=""),"",COUNTIFS('📋 Data Pasien'!$B:$B,B35,'📋 Data Pasien'!$J:$J,C35,'📋 Data Pasien'!$D:$D,250000)) | H35: =IF(OR(B35="",C35=""),"",COUNTIFS('📋 Data Pasien'!$B:$B,B35,'📋 Data Pasien'!$J:$J,C35,'📋 Data Pasien'!$D:$D,300000)) | I35: =IF(C35="","",SUM(D35:H35)) | J35: =IF(C35="","",D35*100000) | K35: =IF(C35="","",E35*150000) | L35: =IF(C35="","",F35*200000) | M35: =IF(C35="","",G35*250000) | N35: =IF(C35="","",H35*300000) | O35: =IF(C35="","",SUM(J35:N35)) | P35: =IF(C35="","",D35*70000+E35*105000+F35*130000+G35*155000+H35*180000) | R35: =IF(C35="","",D35*30000+E35*45000+F35*70000+G35*95000+H35*120000)
A36: =IF(C36<>"",33,"") | D36: =IF(OR(B36="",C36=""),"",COUNTIFS('📋 Data Pasien'!$B:$B,B36,'📋 Data Pasien'!$J:$J,C36,'📋 Data Pasien'!$D:$D,100000)) | E36: =IF(OR(B36="",C36=""),"",COUNTIFS('📋 Data Pasien'!$B:$B,B36,'📋 Data Pasien'!$J:$J,C36,'📋 Data Pasien'!$D:$D,150000)) | F36: =IF(OR(B36="",C36=""),"",COUNTIFS('📋 Data Pasien'!$B:$B,B36,'📋 Data Pasien'!$J:$J,C36,'📋 Data Pasien'!$D:$D,200000)) | G36: =IF(OR(B36="",C36=""),"",COUNTIFS('📋 Data Pasien'!$B:$B,B36,'📋 Data Pasien'!$J:$J,C36,'📋 Data Pasien'!$D:$D,250000)) | H36: =IF(OR(B36="",C36=""),"",COUNTIFS('📋 Data Pasien'!$B:$B,B36,'📋 Data Pasien'!$J:$J,C36,'📋 Data Pasien'!$D:$D,300000)) | I36: =IF(C36="","",SUM(D36:H36)) | J36: =IF(C36="","",D36*100000) | K36: =IF(C36="","",E36*150000) | L36: =IF(C36="","",F36*200000) | M36: =IF(C36="","",G36*250000) | N36: =IF(C36="","",H36*300000) | O36: =IF(C36="","",SUM(J36:N36)) | P36: =IF(C36="","",D36*70000+E36*105000+F36*130000+G36*155000+H36*180000) | R36: =IF(C36="","",D36*30000+E36*45000+F36*70000+G36*95000+H36*120000)
A37: =IF(C37<>"",34,"") | D37: =IF(OR(B37="",C37=""),"",COUNTIFS('📋 Data Pasien'!$B:$B,B37,'📋 Data Pasien'!$J:$J,C37,'📋 Data Pasien'!$D:$D,100000)) | E37: =IF(OR(B37="",C37=""),"",COUNTIFS('📋 Data Pasien'!$B:$B,B37,'📋 Data Pasien'!$J:$J,C37,'📋 Data Pasien'!$D:$D,150000)) | F37: =IF(OR(B37="",C37=""),"",COUNTIFS('📋 Data Pasien'!$B:$B,B37,'📋 Data Pasien'!$J:$J,C37,'📋 Data Pasien'!$D:$D,200000)) | G37: =IF(OR(B37="",C37=""),"",COUNTIFS('📋 Data Pasien'!$B:$B,B37,'📋 Data Pasien'!$J:$J,C37,'📋 Data Pasien'!$D:$D,250000)) | H37: =IF(OR(B37="",C37=""),"",COUNTIFS('📋 Data Pasien'!$B:$B,B37,'📋 Data Pasien'!$J:$J,C37,'📋 Data Pasien'!$D:$D,300000)) | I37: =IF(C37="","",SUM(D37:H37)) | J37: =IF(C37="","",D37*100000) | K37: =IF(C37="","",E37*150000) | L37: =IF(C37="","",F37*200000) | M37: =IF(C37="","",G37*250000) | N37: =IF(C37="","",H37*300000) | O37: =IF(C37="","",SUM(J37:N37)) | P37: =IF(C37="","",D37*70000+E37*105000+F37*130000+G37*155000+H37*180000) | R37: =IF(C37="","",D37*30000+E37*45000+F37*70000+G37*95000+H37*120000)
A38: =IF(C38<>"",35,"") | D38: =IF(OR(B38="",C38=""),"",COUNTIFS('📋 Data Pasien'!$B:$B,B38,'📋 Data Pasien'!$J:$J,C38,'📋 Data Pasien'!$D:$D,100000)) | E38: =IF(OR(B38="",C38=""),"",COUNTIFS('📋 Data Pasien'!$B:$B,B38,'📋 Data Pasien'!$J:$J,C38,'📋 Data Pasien'!$D:$D,150000)) | F38: =IF(OR(B38="",C38=""),"",COUNTIFS('📋 Data Pasien'!$B:$B,B38,'📋 Data Pasien'!$J:$J,C38,'📋 Data Pasien'!$D:$D,200000)) | G38: =IF(OR(B38="",C38=""),"",COUNTIFS('📋 Data Pasien'!$B:$B,B38,'📋 Data Pasien'!$J:$J,C38,'📋 Data Pasien'!$D:$D,250000)) | H38: =IF(OR(B38="",C38=""),"",COUNTIFS('📋 Data Pasien'!$B:$B,B38,'📋 Data Pasien'!$J:$J,C38,'📋 Data Pasien'!$D:$D,300000)) | I38: =IF(C38="","",SUM(D38:H38)) | J38: =IF(C38="","",D38*100000) | K38: =IF(C38="","",E38*150000) | L38: =IF(C38="","",F38*200000) | M38: =IF(C38="","",G38*250000) | N38: =IF(C38="","",H38*300000) | O38: =IF(C38="","",SUM(J38:N38)) | P38: =IF(C38="","",D38*70000+E38*105000+F38*130000+G38*155000+H38*180000) | R38: =IF(C38="","",D38*30000+E38*45000+F38*70000+G38*95000+H38*120000)
A39: =IF(C39<>"",36,"") | D39: =IF(OR(B39="",C39=""),"",COUNTIFS('📋 Data Pasien'!$B:$B,B39,'📋 Data Pasien'!$J:$J,C39,'📋 Data Pasien'!$D:$D,100000)) | E39: =IF(OR(B39="",C39=""),"",COUNTIFS('📋 Data Pasien'!$B:$B,B39,'📋 Data Pasien'!$J:$J,C39,'📋 Data Pasien'!$D:$D,150000)) | F39: =IF(OR(B39="",C39=""),"",COUNTIFS('📋 Data Pasien'!$B:$B,B39,'📋 Data Pasien'!$J:$J,C39,'📋 Data Pasien'!$D:$D,200000)) | G39: =IF(OR(B39="",C39=""),"",COUNTIFS('📋 Data Pasien'!$B:$B,B39,'📋 Data Pasien'!$J:$J,C39,'📋 Data Pasien'!$D:$D,250000)) | H39: =IF(OR(B39="",C39=""),"",COUNTIFS('📋 Data Pasien'!$B:$B,B39,'📋 Data Pasien'!$J:$J,C39,'📋 Data Pasien'!$D:$D,300000)) | I39: =IF(C39="","",SUM(D39:H39)) | J39: =IF(C39="","",D39*100000) | K39: =IF(C39="","",E39*150000) | L39: =IF(C39="","",F39*200000) | M39: =IF(C39="","",G39*250000) | N39: =IF(C39="","",H39*300000) | O39: =IF(C39="","",SUM(J39:N39)) | P39: =IF(C39="","",D39*70000+E39*105000+F39*130000+G39*155000+H39*180000) | R39: =IF(C39="","",D39*30000+E39*45000+F39*70000+G39*95000+H39*120000)
A40: =IF(C40<>"",37,"") | D40: =IF(OR(B40="",C40=""),"",COUNTIFS('📋 Data Pasien'!$B:$B,B40,'📋 Data Pasien'!$J:$J,C40,'📋 Data Pasien'!$D:$D,100000)) | E40: =IF(OR(B40="",C40=""),"",COUNTIFS('📋 Data Pasien'!$B:$B,B40,'📋 Data Pasien'!$J:$J,C40,'📋 Data Pasien'!$D:$D,150000)) | F40: =IF(OR(B40="",C40=""),"",COUNTIFS('📋 Data Pasien'!$B:$B,B40,'📋 Data Pasien'!$J:$J,C40,'📋 Data Pasien'!$D:$D,200000)) | G40: =IF(OR(B40="",C40=""),"",COUNTIFS('📋 Data Pasien'!$B:$B,B40,'📋 Data Pasien'!$J:$J,C40,'📋 Data Pasien'!$D:$D,250000)) | H40: =IF(OR(B40="",C40=""),"",COUNTIFS('📋 Data Pasien'!$B:$B,B40,'📋 Data Pasien'!$J:$J,C40,'📋 Data Pasien'!$D:$D,300000)) | I40: =IF(C40="","",SUM(D40:H40)) | J40: =IF(C40="","",D40*100000) | K40: =IF(C40="","",E40*150000) | L40: =IF(C40="","",F40*200000) | M40: =IF(C40="","",G40*250000) | N40: =IF(C40="","",H40*300000) | O40: =IF(C40="","",SUM(J40:N40)) | P40: =IF(C40="","",D40*70000+E40*105000+F40*130000+G40*155000+H40*180000) | R40: =IF(C40="","",D40*30000+E40*45000+F40*70000+G40*95000+H40*120000)
...

Sheet Rekap Per Dokter
A1: REKAP FEE PER DOKTER — OTOMATIS dari Input Harian & Pembayaran Dokter
A2: 🔄 Tambah baris di Input Harian → rekap ini update otomatis | Status bayar dari Pembayaran Dokter
A3: Nama Dokter | B3: Total Hari Praktek | C3: Pasien 100rb | D3: Pasien 150rb | E3: Pasien 200rb | F3: Pasien 250rb | G3: Pasien 300rb | H3: Total Pasien | I3: Fee Dokter (Rp) | J3: Fee Klinik (Rp) | K3: Status Pembayaran | L3: Sudah Dibayar (Rp) | M3: Sisa Belum Dibayar (Rp) | N3: KETERANGAN
A4: dr. ARIF | B4: =COUNTIF('Input Harian'!$C:$C,"dr. ARIF") | C4: =SUMIF('Input Harian'!$C:$C,"dr. ARIF",'Input Harian'!$D:$D) | D4: =SUMIF('Input Harian'!$C:$C,"dr. ARIF",'Input Harian'!$E:$E) | E4: =SUMIF('Input Harian'!$C:$C,"dr. ARIF",'Input Harian'!$F:$F) | F4: =SUMIF('Input Harian'!$C:$C,"dr. ARIF",'Input Harian'!$G:$G) | G4: =SUMIF('Input Harian'!$C:$C,"dr. ARIF",'Input Harian'!$H:$H) | H4: =SUM(C4:G4) | I4: =SUMIF('Input Harian'!$C:$C,"dr. ARIF",'Input Harian'!$P:$P) | J4: =SUMIF('Input Harian'!$C:$C,"dr. ARIF",'Input Harian'!$R:$R) | K4: ='💰 Pembayaran Dokter'!E6 | L4: ='💰 Pembayaran Dokter'!C6 | M4: =I4-L4 | N4: guarantee fee 200rb
A5: dr. HAWA | B5: =COUNTIF('Input Harian'!$C:$C,"dr. HAWA") | C5: =SUMIF('Input Harian'!$C:$C,"dr. HAWA",'Input Harian'!$D:$D) | D5: =SUMIF('Input Harian'!$C:$C,"dr. HAWA",'Input Harian'!$E:$E) | E5: =SUMIF('Input Harian'!$C:$C,"dr. HAWA",'Input Harian'!$F:$F) | F5: =SUMIF('Input Harian'!$C:$C,"dr. HAWA",'Input Harian'!$G:$G) | G5: =SUMIF('Input Harian'!$C:$C,"dr. HAWA",'Input Harian'!$H:$H) | H5: =SUM(C5:G5) | I5: =SUMIF('Input Harian'!$C:$C,"dr. HAWA",'Input Harian'!$P:$P) | J5: =SUMIF('Input Harian'!$C:$C,"dr. HAWA",'Input Harian'!$R:$R) | K5: ='💰 Pembayaran Dokter'!E7 | L5: ='💰 Pembayaran Dokter'!C7 | M5: =I5-L5
A6: dr. JOJO | B6: =COUNTIF('Input Harian'!$C:$C,"dr. JOJO") | C6: =SUMIF('Input Harian'!$C:$C,"dr. JOJO",'Input Harian'!$D:$D) | D6: =SUMIF('Input Harian'!$C:$C,"dr. JOJO",'Input Harian'!$E:$E) | E6: =SUMIF('Input Harian'!$C:$C,"dr. JOJO",'Input Harian'!$F:$F) | F6: =SUMIF('Input Harian'!$C:$C,"dr. JOJO",'Input Harian'!$G:$G) | G6: =SUMIF('Input Harian'!$C:$C,"dr. JOJO",'Input Harian'!$H:$H) | H6: =SUM(C6:G6) | I6: =SUMIF('Input Harian'!$C:$C,"dr. JOJO",'Input Harian'!$P:$P) | J6: =SUMIF('Input Harian'!$C:$C,"dr. JOJO",'Input Harian'!$R:$R) | K6: ='💰 Pembayaran Dokter'!E8 | L6: 3550000 | M6: =I6-L6
A7: GRAND TOTAL | B7: =SUM(B4:B6) | C7: =SUM(C4:C6) | D7: =SUM(D4:D6) | E7: =SUM(E4:E6) | F7: =SUM(F4:F6) | G7: =SUM(G4:G6) | H7: =SUM(H4:H6) | I7: =SUM(I4:I6) | J7: =SUM(J4:J6) | K7: =IF(M7=0,"✅ SEMUA LUNAS","⏳ Ada yang Belum") | L7: =SUM(L4:L6) | M7: =SUM(M4:M6)

Sheet 💳 Detail Per Dokter
A1: 💳 LAPORAN DETAIL PENARIKAN & FEE PER DOKTER
A2: Konsultasi Rp150.000: Dokter 70% / Klinik 30% | Tindakan Tambahan: Dokter 50% / Klinik 50% | Dicetak: 12 May 2026
A3: 👨‍⚕️ dr. ARIF
A4: No | B4: Tanggal | C4: Ps. 100rb | D4: Ps. 150rb | E4: Ps. 200rb | F4: Ps. 250rb | G4: Ps. 300rb | H4: Total Pasien | I4: Total Penarikan | J4: Fee Dokter (KONSULTASI 70%+TINDAKAN 50%) | K4: Fee Klinik (30%+50%) | L4: Keterangan
A5: 1 | B5: 46141 | C5: =IFERROR(COUNTIFS('📋 Data Pasien'!$B:$B,B5,'📋 Data Pasien'!$J:$J,"dr. ARIF",'📋 Data Pasien'!$D:$D,100000),0) | D5: =IFERROR(COUNTIFS('📋 Data Pasien'!$B:$B,B5,'📋 Data Pasien'!$J:$J,"dr. ARIF",'📋 Data Pasien'!$D:$D,150000),0) | E5: =IFERROR(COUNTIFS('📋 Data Pasien'!$B:$B,B5,'📋 Data Pasien'!$J:$J,"dr. ARIF",'📋 Data Pasien'!$D:$D,200000),0) | F5: =IFERROR(COUNTIFS('📋 Data Pasien'!$B:$B,B5,'📋 Data Pasien'!$J:$J,"dr. ARIF",'📋 Data Pasien'!$D:$D,250000),0) | G5: =IFERROR(COUNTIFS('📋 Data Pasien'!$B:$B,B5,'📋 Data Pasien'!$J:$J,"dr. ARIF",'📋 Data Pasien'!$D:$D,300000),0) | H5: =SUM(C5:G5) | I5: =C5*100000+D5*150000+E5*200000+F5*250000+G5*300000 | J5: =C5*70000+D5*105000+E5*130000+F5*155000+G5*180000 | K5: =C5*30000+D5*45000+E5*70000+F5*95000+G5*120000
A6: 2 | B6: 46142 | C6: =IFERROR(COUNTIFS('📋 Data Pasien'!$B:$B,B6,'📋 Data Pasien'!$J:$J,"dr. ARIF",'📋 Data Pasien'!$D:$D,100000),0) | D6: =IFERROR(COUNTIFS('📋 Data Pasien'!$B:$B,B6,'📋 Data Pasien'!$J:$J,"dr. ARIF",'📋 Data Pasien'!$D:$D,150000),0) | E6: =IFERROR(COUNTIFS('📋 Data Pasien'!$B:$B,B6,'📋 Data Pasien'!$J:$J,"dr. ARIF",'📋 Data Pasien'!$D:$D,200000),0) | F6: =IFERROR(COUNTIFS('📋 Data Pasien'!$B:$B,B6,'📋 Data Pasien'!$J:$J,"dr. ARIF",'📋 Data Pasien'!$D:$D,250000),0) | G6: =IFERROR(COUNTIFS('📋 Data Pasien'!$B:$B,B6,'📋 Data Pasien'!$J:$J,"dr. ARIF",'📋 Data Pasien'!$D:$D,300000),0) | H6: =SUM(C6:G6) | I6: =C6*100000+D6*150000+E6*200000+F6*250000+G6*300000 | J6: 200000 | K6: 0 | L6: guarantee fee 200rb
A7: 3 | B7: 46146 | C7: =IFERROR(COUNTIFS('📋 Data Pasien'!$B:$B,B7,'📋 Data Pasien'!$J:$J,"dr. ARIF",'📋 Data Pasien'!$D:$D,100000),0) | D7: =IFERROR(COUNTIFS('📋 Data Pasien'!$B:$B,B7,'📋 Data Pasien'!$J:$J,"dr. ARIF",'📋 Data Pasien'!$D:$D,150000),0) | E7: =IFERROR(COUNTIFS('📋 Data Pasien'!$B:$B,B7,'📋 Data Pasien'!$J:$J,"dr. ARIF",'📋 Data Pasien'!$D:$D,200000),0) | F7: =IFERROR(COUNTIFS('📋 Data Pasien'!$B:$B,B7,'📋 Data Pasien'!$J:$J,"dr. ARIF",'📋 Data Pasien'!$D:$D,250000),0) | G7: =IFERROR(COUNTIFS('📋 Data Pasien'!$B:$B,B7,'📋 Data Pasien'!$J:$J,"dr. ARIF",'📋 Data Pasien'!$D:$D,300000),0) | H7: =SUM(C7:G7) | I7: =C7*100000+D7*150000+E7*200000+F7*250000+G7*300000 | J7: =C7*70000+D7*105000+E7*130000+F7*155000+G7*180000 | K7: =C7*30000+D7*45000+E7*70000+F7*95000+G7*120000
A8: 4 | B8: 46148 | C8: =IFERROR(COUNTIFS('📋 Data Pasien'!$B:$B,B8,'📋 Data Pasien'!$J:$J,"dr. ARIF",'📋 Data Pasien'!$D:$D,100000),0) | D8: =IFERROR(COUNTIFS('📋 Data Pasien'!$B:$B,B8,'📋 Data Pasien'!$J:$J,"dr. ARIF",'📋 Data Pasien'!$D:$D,150000),0) | E8: =IFERROR(COUNTIFS('📋 Data Pasien'!$B:$B,B8,'📋 Data Pasien'!$J:$J,"dr. ARIF",'📋 Data Pasien'!$D:$D,200000),0) | F8: =IFERROR(COUNTIFS('📋 Data Pasien'!$B:$B,B8,'📋 Data Pasien'!$J:$J,"dr. ARIF",'📋 Data Pasien'!$D:$D,250000),0) | G8: =IFERROR(COUNTIFS('📋 Data Pasien'!$B:$B,B8,'📋 Data Pasien'!$J:$J,"dr. ARIF",'📋 Data Pasien'!$D:$D,300000),0) | H8: =SUM(C8:G8) | I8: =C8*100000+D8*150000+E8*200000+F8*250000+G8*300000 | J8: =C8*70000+D8*105000+E8*130000+F8*155000+G8*180000 | K8: =C8*30000+D8*45000+E8*70000+F8*95000+G8*120000
A9: 5 | B9: 46149 | C9: =IFERROR(COUNTIFS('📋 Data Pasien'!$B:$B,B9,'📋 Data Pasien'!$J:$J,"dr. ARIF",'📋 Data Pasien'!$D:$D,100000),0) | D9: =IFERROR(COUNTIFS('📋 Data Pasien'!$B:$B,B9,'📋 Data Pasien'!$J:$J,"dr. ARIF",'📋 Data Pasien'!$D:$D,150000),0) | E9: =IFERROR(COUNTIFS('📋 Data Pasien'!$B:$B,B9,'📋 Data Pasien'!$J:$J,"dr. ARIF",'📋 Data Pasien'!$D:$D,200000),0) | F9: =IFERROR(COUNTIFS('📋 Data Pasien'!$B:$B,B9,'📋 Data Pasien'!$J:$J,"dr. ARIF",'📋 Data Pasien'!$D:$D,250000),0) | G9: =IFERROR(COUNTIFS('📋 Data Pasien'!$B:$B,B9,'📋 Data Pasien'!$J:$J,"dr. ARIF",'📋 Data Pasien'!$D:$D,300000),0) | H9: =SUM(C9:G9) | I9: =C9*100000+D9*150000+E9*200000+F9*250000+G9*300000 | J9: =C9*70000+D9*105000+E9*130000+F9*155000+G9*180000 | K9: =C9*30000+D9*45000+E9*70000+F9*95000+G9*120000
A10: 6 | B10: 46155 | C10: =IFERROR(COUNTIFS('📋 Data Pasien'!$B:$B,B10,'📋 Data Pasien'!$J:$J,"dr. ARIF",'📋 Data Pasien'!$D:$D,100000),0) | D10: =IFERROR(COUNTIFS('📋 Data Pasien'!$B:$B,B10,'📋 Data Pasien'!$J:$J,"dr. ARIF",'📋 Data Pasien'!$D:$D,150000),0) | E10: =IFERROR(COUNTIFS('📋 Data Pasien'!$B:$B,B10,'📋 Data Pasien'!$J:$J,"dr. ARIF",'📋 Data Pasien'!$D:$D,200000),0) | F10: =IFERROR(COUNTIFS('📋 Data Pasien'!$B:$B,B10,'📋 Data Pasien'!$J:$J,"dr. ARIF",'📋 Data Pasien'!$D:$D,250000),0) | G10: =IFERROR(COUNTIFS('📋 Data Pasien'!$B:$B,B10,'📋 Data Pasien'!$J:$J,"dr. ARIF",'📋 Data Pasien'!$D:$D,300000),0) | H10: =SUM(C10:G10) | I10: =C10*100000+D10*150000+E10*200000+F10*250000+G10*300000 | J10: =C10*70000+D10*105000+E10*130000+F10*155000+G10*180000 | K10: =C10*30000+D10*45000+E10*70000+F10*95000+G10*120000
A11: 7 | B11: 46156 | C11: 1 | D11: 3 | E11: 3 | F11: 0 | G11: 0 | H11: =SUM(C11:G11) | I11: =C11*100000+D11*150000+E11*200000+F11*250000+G11*300000 | J11: =C11*70000+D11*105000+E11*130000+F11*155000+G11*180000 | K11: =C11*30000+D11*45000+E11*70000+F11*95000+G11*120000
A13: SUBTOTAL dr. ARIF | C13: =SUM(C5:C12) | D13: =SUM(D5:D12) | E13: =SUM(E5:E12) | F13: =SUM(F5:F12) | G13: =SUM(G5:G12) | H13: =SUM(H5:H12) | I13: =SUM(I5:I12) | J13: =SUM(J5:J12) | K13: =SUM(K5:K12)
A15: 👨‍⚕️ dr. HAWA
A16: No | B16: Tanggal | C16: Ps. 100rb | D16: Ps. 150rb | E16: Ps. 200rb | F16: Ps. 250rb | G16: Ps. 300rb | H16: Total Pasien | I16: Total Penarikan | J16: Fee Dokter (KONSULTASI 70%+TINDAKAN 50%) | K16: Fee Klinik (30%+50%) | L16: Keterangan
A17: 1 | B17: 46140 | C17: =IFERROR(COUNTIFS('📋 Data Pasien'!$B:$B,B16,'📋 Data Pasien'!$J:$J,"dr. HAWA",'📋 Data Pasien'!$D:$D,100000),0) | D17: =IFERROR(COUNTIFS('📋 Data Pasien'!$B:$B,B16,'📋 Data Pasien'!$J:$J,"dr. HAWA",'📋 Data Pasien'!$D:$D,150000),0) | E17: =IFERROR(COUNTIFS('📋 Data Pasien'!$B:$B,B16,'📋 Data Pasien'!$J:$J,"dr. HAWA",'📋 Data Pasien'!$D:$D,200000),0) | F17: =IFERROR(COUNTIFS('📋 Data Pasien'!$B:$B,B16,'📋 Data Pasien'!$J:$J,"dr. HAWA",'📋 Data Pasien'!$D:$D,250000),0) | G17: =IFERROR(COUNTIFS('📋 Data Pasien'!$B:$B,B16,'📋 Data Pasien'!$J:$J,"dr. HAWA",'📋 Data Pasien'!$D:$D,300000),0) | H17: =SUM(C16:G16) | I17: =C17*100000+D17*150000+E17*200000+F17*250000+G17*300000 | J17: =C17*70000+D17*105000+E17*130000+F17*155000+G17*180000 | K17: =C17*30000+D17*45000+E17*70000+F17*95000+G17*120000
A18: 2 | B18: 46144 | C18: =IFERROR(COUNTIFS('📋 Data Pasien'!$B:$B,B17,'📋 Data Pasien'!$J:$J,"dr. HAWA",'📋 Data Pasien'!$D:$D,100000),0) | D18: =IFERROR(COUNTIFS('📋 Data Pasien'!$B:$B,B17,'📋 Data Pasien'!$J:$J,"dr. HAWA",'📋 Data Pasien'!$D:$D,150000),0) | E18: =IFERROR(COUNTIFS('📋 Data Pasien'!$B:$B,B17,'📋 Data Pasien'!$J:$J,"dr. HAWA",'📋 Data Pasien'!$D:$D,200000),0) | F18: =IFERROR(COUNTIFS('📋 Data Pasien'!$B:$B,B17,'📋 Data Pasien'!$J:$J,"dr. HAWA",'📋 Data Pasien'!$D:$D,250000),0) | G18: =IFERROR(COUNTIFS('📋 Data Pasien'!$B:$B,B17,'📋 Data Pasien'!$J:$J,"dr. HAWA",'📋 Data Pasien'!$D:$D,300000),0) | H18: =SUM(C17:G17) | I18: =C18*100000+D18*150000+E18*200000+F18*250000+G18*300000 | J18: =C18*70000+D18*105000+E18*130000+F18*155000+G18*180000 | K18: =C18*30000+D18*45000+E18*70000+F18*95000+G18*120000
A19: 3 | B19: 46145 | C19: =IFERROR(COUNTIFS('📋 Data Pasien'!$B:$B,B18,'📋 Data Pasien'!$J:$J,"dr. HAWA",'📋 Data Pasien'!$D:$D,100000),0) | D19: =IFERROR(COUNTIFS('📋 Data Pasien'!$B:$B,B18,'📋 Data Pasien'!$J:$J,"dr. HAWA",'📋 Data Pasien'!$D:$D,150000),0) | E19: =IFERROR(COUNTIFS('📋 Data Pasien'!$B:$B,B18,'📋 Data Pasien'!$J:$J,"dr. HAWA",'📋 Data Pasien'!$D:$D,200000),0) | F19: =IFERROR(COUNTIFS('📋 Data Pasien'!$B:$B,B18,'📋 Data Pasien'!$J:$J,"dr. HAWA",'📋 Data Pasien'!$D:$D,250000),0) | G19: =IFERROR(COUNTIFS('📋 Data Pasien'!$B:$B,B18,'📋 Data Pasien'!$J:$J,"dr. HAWA",'📋 Data Pasien'!$D:$D,300000),0) | H19: =SUM(C18:G18) | I19: =C19*100000+D19*150000+E19*200000+F19*250000+G19*300000 | J19: =C19*70000+D19*105000+E19*130000+F19*155000+G19*180000 | K19: =C19*30000+D19*45000+E19*70000+F19*95000+G19*120000
A20: 4 | B20: 46147 | C20: =IFERROR(COUNTIFS('📋 Data Pasien'!$B:$B,B19,'📋 Data Pasien'!$J:$J,"dr. HAWA",'📋 Data Pasien'!$D:$D,100000),0) | D20: =IFERROR(COUNTIFS('📋 Data Pasien'!$B:$B,B19,'📋 Data Pasien'!$J:$J,"dr. HAWA",'📋 Data Pasien'!$D:$D,150000),0) | E20: =IFERROR(COUNTIFS('📋 Data Pasien'!$B:$B,B19,'📋 Data Pasien'!$J:$J,"dr. HAWA",'📋 Data Pasien'!$D:$D,200000),0) | F20: =IFERROR(COUNTIFS('📋 Data Pasien'!$B:$B,B19,'📋 Data Pasien'!$J:$J,"dr. HAWA",'📋 Data Pasien'!$D:$D,250000),0) | G20: =IFERROR(COUNTIFS('📋 Data Pasien'!$B:$B,B19,'📋 Data Pasien'!$J:$J,"dr. HAWA",'📋 Data Pasien'!$D:$D,300000),0) | H20: =SUM(C19:G19) | I20: =C20*100000+D20*150000+E20*200000+F20*250000+G20*300000 | J20: =C20*70000+D20*105000+E20*130000+F20*155000+G20*180000 | K20: =C20*30000+D20*45000+E20*70000+F20*95000+G20*120000
A21: 5 | B21: 46151 | C21: =IFERROR(COUNTIFS('📋 Data Pasien'!$B:$B,B20,'📋 Data Pasien'!$J:$J,"dr. HAWA",'📋 Data Pasien'!$D:$D,100000),0) | D21: =IFERROR(COUNTIFS('📋 Data Pasien'!$B:$B,B20,'📋 Data Pasien'!$J:$J,"dr. HAWA",'📋 Data Pasien'!$D:$D,150000),0) | E21: =IFERROR(COUNTIFS('📋 Data Pasien'!$B:$B,B20,'📋 Data Pasien'!$J:$J,"dr. HAWA",'📋 Data Pasien'!$D:$D,200000),0) | F21: =IFERROR(COUNTIFS('📋 Data Pasien'!$B:$B,B20,'📋 Data Pasien'!$J:$J,"dr. HAWA",'📋 Data Pasien'!$D:$D,250000),0) | G21: =IFERROR(COUNTIFS('📋 Data Pasien'!$B:$B,B20,'📋 Data Pasien'!$J:$J,"dr. HAWA",'📋 Data Pasien'!$D:$D,300000),0) | H21: =SUM(C20:G20) | I21: =C21*100000+D21*150000+E21*200000+F21*250000+G21*300000 | J21: =C21*70000+D21*105000+E21*130000+F21*155000+G21*180000 | K21: =C21*30000+D21*45000+E21*70000+F21*95000+G21*120000
A22: 6 | B22: 46152 | C22: =IFERROR(COUNTIFS('📋 Data Pasien'!$B:$B,B21,'📋 Data Pasien'!$J:$J,"dr. HAWA",'📋 Data Pasien'!$D:$D,100000),0) | D22: =IFERROR(COUNTIFS('📋 Data Pasien'!$B:$B,B21,'📋 Data Pasien'!$J:$J,"dr. HAWA",'📋 Data Pasien'!$D:$D,150000),0) | E22: =IFERROR(COUNTIFS('📋 Data Pasien'!$B:$B,B21,'📋 Data Pasien'!$J:$J,"dr. HAWA",'📋 Data Pasien'!$D:$D,200000),0) | F22: =IFERROR(COUNTIFS('📋 Data Pasien'!$B:$B,B21,'📋 Data Pasien'!$J:$J,"dr. HAWA",'📋 Data Pasien'!$D:$D,250000),0) | G22: =IFERROR(COUNTIFS('📋 Data Pasien'!$B:$B,B21,'📋 Data Pasien'!$J:$J,"dr. HAWA",'📋 Data Pasien'!$D:$D,300000),0) | H22: =SUM(C21:G21) | I22: =C22*100000+D22*150000+E22*200000+F22*250000+G22*300000 | J22: =C22*70000+D22*105000+E22*130000+F22*155000+G22*180000 | K22: =C22*30000+D22*45000+E22*70000+F22*95000+G22*120000
A23: 7 | B23: 46154 | C23: =IFERROR(COUNTIFS('📋 Data Pasien'!$B:$B,B22,'📋 Data Pasien'!$J:$J,"dr. HAWA",'📋 Data Pasien'!$D:$D,100000),0) | D23: =IFERROR(COUNTIFS('📋 Data Pasien'!$B:$B,B22,'📋 Data Pasien'!$J:$J,"dr. HAWA",'📋 Data Pasien'!$D:$D,150000),0) | E23: =IFERROR(COUNTIFS('📋 Data Pasien'!$B:$B,B22,'📋 Data Pasien'!$J:$J,"dr. HAWA",'📋 Data Pasien'!$D:$D,200000),0) | F23: =IFERROR(COUNTIFS('📋 Data Pasien'!$B:$B,B22,'📋 Data Pasien'!$J:$J,"dr. HAWA",'📋 Data Pasien'!$D:$D,250000),0) | G23: =IFERROR(COUNTIFS('📋 Data Pasien'!$B:$B,B22,'📋 Data Pasien'!$J:$J,"dr. HAWA",'📋 Data Pasien'!$D:$D,300000),0) | H23: =SUM(C22:G22) | I23: =C23*100000+D23*150000+E23*200000+F23*250000+G23*300000 | J23: =C23*70000+D23*105000+E23*130000+F23*155000+G23*180000 | K23: =C23*30000+D23*45000+E23*70000+F23*95000+G23*120000
A26: SUBTOTAL dr. HAWA | C26: =SUM(C17:C23) | D26: =SUM(D17:D23) | E26: =SUM(E17:E23) | F26: =SUM(F17:F23) | G26: =SUM(G17:G23) | H26: =SUM(H17:H23) | I26: =SUM(I17:I23) | J26: =SUM(J17:J23) | K26: =SUM(K17:K23)
A28: 👨‍⚕️ dr. JOJO
A29: No | B29: Tanggal | C29: Ps. 100rb | D29: Ps. 150rb | E29: Ps. 200rb | F29: Ps. 250rb | G29: Ps. 300rb | H29: Total Pasien | I29: Total Penarikan | J29: Fee Dokter (KONSULTASI 70%+TINDAKAN 50%) | K29: Fee Klinik (30%+50%) | L29: Keterangan
A30: 1 | B30: 46150 | C30: =IFERROR(COUNTIFS('📋 Data Pasien'!$B:$B,B30,'📋 Data Pasien'!$J:$J,"dr. JOJO",'📋 Data Pasien'!$D:$D,100000),0) | D30: =IFERROR(COUNTIFS('📋 Data Pasien'!$B:$B,B30,'📋 Data Pasien'!$J:$J,"dr. JOJO",'📋 Data Pasien'!$D:$D,150000),0) | E30: =IFERROR(COUNTIFS('📋 Data Pasien'!$B:$B,B30,'📋 Data Pasien'!$J:$J,"dr. JOJO",'📋 Data Pasien'!$D:$D,200000),0) | F30: =IFERROR(COUNTIFS('📋 Data Pasien'!$B:$B,B30,'📋 Data Pasien'!$J:$J,"dr. JOJO",'📋 Data Pasien'!$D:$D,250000),0) | G30: =IFERROR(COUNTIFS('📋 Data Pasien'!$B:$B,B30,'📋 Data Pasien'!$J:$J,"dr. JOJO",'📋 Data Pasien'!$D:$D,300000),0) | H30: =SUM(C30:G30) | I30: =C30*100000+D30*150000+E30*200000+F30*250000+G30*300000 | J30: =C30*70000+D30*105000+E30*130000+F30*155000+G30*180000 | K30: =C30*30000+D30*45000+E30*70000+F30*95000+G30*120000
